Workbook

Sheet README
B1: LifeMap calculators
B2: Version 2.8 · 9 Oct 2026 · built from LifeMap-Customer-Journey prototype (CALCS and Settings). Since 2.7: date of birth replaces age (calendar-year cashflow), the over-80 State Pension increase only when a State Pension counts, and the Report spec sheet. Since 2.4: the main plan in Make my plan (eight sheets starting "Plan ..." and the Calculation register), audit fixes to the calculators (see "Audit fixes applied"), an example column on every calculator input block, law figures on the Plan sheets read from Assumptions, up to 20 saved-for goals, data validation on the Plan sheets and Settings, and the same "Choose your ... to see this" words and order as the app on every calculator. Since 2.6 (journey spec section 27): only retirement age, plan-until age, inflation and a working partner's retirement age block the plan (the gate card says "we need N things"); every LifeMap standard is used automatically and is labelled "Set by LifeMap"; a market rate you do not give uses the suggested or planning rate ("Assumed: add yours"); any retirement age from your age + 1 is allowed, with the pension from the access age (60, or 50 for some occupational schemes) and the years before it paid from savings; a goal dated before today reads "Date has passed". The four UI sheets (UI Guide, UI Calculators, UI Screens, UI Make my plan) are added by tools/build_ui_sheets.py.
B3: Fill example values? (Yes/No) | C3: No | D3: Example only: Yes fills every blank input with its grey figure, so testers see numbers. Default No (blank template).
B4: How to use
B5: • Open a calculator from the list below. Fill the yellow cells (blue text): everything else updates on its own.
B6: • Every number is one of three types (journey spec §14, §18, §27). Type 1, set by Government (tax, USC, PRSI, relief %, lump-sum bands, DIRT, exit tax, Central Bank limits, full State Pension and benefit rates): on the Assumptions sheet, not an input. Type 2, a market rate or a figure you enter yourself (mortgage rate, card APR, fund charges, the State Pension you will get …): a yellow input with a suggested figure and its source, or "Usually between X and Y (source)" where an official range exists; on a calculator it stays blank until you add it, in the plan a blank one uses the suggested published rate (mortgage and loans) or the planning rate (cards 20%) and is labelled "Assumed: add yours". Type 3, a LifeMap standard (growth rates, pay rises, emergency months, drawdown timing, retirement multiple, pension access age …): the calculator and the plan start from the standard ("Set by LifeMap"); type your own and it is "Your choice". Only four things are never filled in for you: retirement age, plan-until age, inflation, and a working partner's retirement age.
B7: • Your own figures stay blank: a calculator result that needs one (a market rate, the State Pension, Illness Benefit, your age, the retirement age) shows "Choose your … to see this" or "Add your … to see this". A LifeMap standard never blocks a result. Set "Fill example values?" (above) to Yes to fill every blank input with its grey "Example only" figure (the standard, or the sample customer's figure).
B8: • Each input cell shows its unit and allowed range when you click it, and refuses values outside it. The default is in the cell note and at the far right.
B9: • Market rates (mortgage, loans, cards, deposits, buying fees, fund charges) are never pre-filled on a calculator. Beside each is a suggested rate with its source, from the Settings sheet: by default Central Bank of Ireland averages with their month (journey spec §18, §19). In the plan, a rate you do not give uses that suggestion (mortgage and loans) or the planning rate (cards 20%) and says "Assumed: add yours". A partner can put its own rates and name there ("Suggested by …"). Law values cannot be changed.
B10: • Facts and law (tax bands, State rates, Central Bank rules, stamp duty, lump-sum bands …) are on the Assumptions sheet, the Irish rules register (Irish rules 2026 · checked 2 Oct 2026). Take-home pay is worked out on the Tax engine sheet, which C25 and C26 use.
B11: • Results are in the green box, each with its formula written out beside it. Formulas use names (e.g. =Amount*(1+Inflation)^Years) so they read like the maths.
B12: • Inflation is the client's own choice: the yellow "Inflation you expect" cell on each calculator that uses it starts blank. While it is blank, results that need it say "Choose your inflation rate to see this"; 0% is a real choice (no adjustment for prices).
B13: • Statements: grey-blue cells under "FROM YOUR STATEMENT" are filled by the document reader. The FIGURE USED box uses the statement figure if there is one, otherwise your typed figure, and says which. See the "Document reader spec" sheet.
B14: • The workbook recalculates automatically, including when it is opened. No sheet or workbook protection is applied: this is an engineering template, so formulas and inputs can be edited. Keep the yellow cells for typing and leave formulas alone.
B15: • Settings sheet: every standard, its wording and source, and the partner name in one block (defined names Set_*). "Your lists": loans, cards, pensions and policies, one row each; the calculators use the totals when their own cell is left blank.
... B30: Calculators
B31: No. | C31: Calculator (click to open) | D31: Question it answers | E31: Category
B32: C01 | C32: =HYPERLINK("#'C01 Borrowing'!A1","How much could I borrow?") -> How much could I borrow? | D32: What home price could be within reach? | E32: Home & Mortgage
B33: C02 | C33: =HYPERLINK("#'C02 Mortgage repayment'!A1","Monthly mortgage repayment") -> Monthly mortgage repayment | D33: What would my monthly repayment be? | E33: Home & Mortgage
B34: C03 | C34: =HYPERLINK("#'C03 Deposit'!A1","Deposit calculator") -> Deposit calculator | D34: How long until I have my deposit? | E34: Home & Mortgage
B35: C04 | C35: =HYPERLINK("#'C04 Mortgage overpayment'!A1","Mortgage overpayment") -> Mortgage overpayment | D35: What if I paid a little extra each month? | E35: Home & Mortgage
B36: C05 | C36: =HYPERLINK("#'C05 Interest rate impact'!A1","Interest-rate impact") -> Interest-rate impact | D36: What if my mortgage rate changed? | E36: Home & Mortgage
B37: C06 | C37: =HYPERLINK("#'C06 Term comparison'!A1","Mortgage term comparison") -> Mortgage term comparison | D37: Shorter or longer term: what is the trade-off? | E37: Home & Mortgage
B38: C07 | C38: =HYPERLINK("#'C07 Rent vs buy'!A1","Rent vs buy") -> Rent vs buy | D38: How do renting and buying compare over time? | E38: Home & Mortgage
B39: C08 | C39: =HYPERLINK("#'C08 Goal planner'!A1","Goal planner") -> Goal planner | D39: How much a month to reach my goal? | E39: Savings & Goals
B40: C09 | C40: =HYPERLINK("#'C09 Compound growth'!A1","Compound growth") -> Compound growth | D40: What could regular saving grow into? | E40: Savings & Goals
B41: C10 | C41: =HYPERLINK("#'C10 Lump sum growth'!A1","Lump-sum growth") -> Lump-sum growth | D41: What could a one-off amount become? | E41: Investments
B42: C11 | C42: =HYPERLINK("#'C11 Emergency fund'!A1","Emergency fund") -> Emergency fund | D42: How strong is my emergency fund? | E42: Savings & Goals
B43: C12 | C43: =HYPERLINK("#'C12 Retirement projection'!A1","Retirement projection") -> Retirement projection | D43: Could your current path fund the retirement you want? | E43: Pensions & Retirement
B44: C13 | C44: =HYPERLINK("#'C13 Contribution impact'!A1","Contribution impact") -> Contribution impact | D44: What difference would a small increase make? | E44: Pensions & Retirement
B45: C14 | C45: =HYPERLINK("#'C14 AVC impact'!A1","AVC impact") -> AVC impact | D45: What could extra voluntary contributions add? | E45: Pensions & Retirement
B46: C15 | C46: =HYPERLINK("#'C15 Will my money last'!A1","Will my money last?") -> Will my money last? | D46: How long could my retirement savings last? | E46: Pensions & Retirement
B47: C16 | C47: =HYPERLINK("#'C16 Drawdown scenarios'!A1","Retirement drawdown scenarios") -> Retirement drawdown scenarios | D47: How do different growth rates change things? | E47: Pensions & Retirement
B48: C17 | C48: =HYPERLINK("#'C17 Inflation adjusted return'!A1","Inflation-adjusted return") -> Inflation-adjusted return | D48: What is my money really worth in future? | E48: Investments
B49: C18 | C49: =HYPERLINK("#'C18 Regular investing'!A1","Regular investing") -> Regular investing | D49: What could investing monthly build? | E49: Investments
B50: C19 | C50: =HYPERLINK("#'C19 Fees impact'!A1","Fees impact") -> Fees impact | D50: How much do fees really cost over time? | E50: Investments
B51: C20 | C51: =HYPERLINK("#'C20 Risk and return'!A1","Risk & return simulator") -> Risk & return simulator | D51: What range of outcomes might each style have? | E51: Investments
B52: C21 | C52: =HYPERLINK("#'C21 Life cover'!A1","Life cover estimator") -> Life cover estimator | D52: How much cover might my family need? | E52: Protection
B53: C22 | C53: =HYPERLINK("#'C22 Income protection gap'!A1","Income protection gap") -> Income protection gap | D53: How long could I cope if I couldn't work? | E53: Protection
B54: C23 | C54: =HYPERLINK("#'C23 Mortgage protection'!A1","Mortgage protection") -> Mortgage protection | D54: What cover would clear my mortgage? | E54: Protection
...

Sheet C01 Borrowing
B1: C01 · How much could I borrow? | E1: Category: Home & Mortgage · prototype id: borrow
B2: Question it answers: What home price could be within reach? | E2: =IF(Fill_Example="Yes","Example values are ON (README): grey Example only figures fill blank inputs.","Blank template: fill the yellow inputs (or switch on example values on the README).") -> Blank template: fill the yellow inputs (or switch on example values on the README).
B3: ="Applies the Central Bank limits ("&LTI_FTB&"× or "&LTI_SSB&"×"&" income, "&TEXT(LTV_Max,"0%")&" loan-to-value) to show the most you could borrow and the home price that gives, after stamp duty and fees." -> Applies the Central Bank limits (4× or 3.5× income, 90% loan-to-value) to show the most you could borrow and the home price that gives, after stamp duty and fees.
B5: INPUTS | C5: Your figure | D5: Unit | E5: Allowed | F5: Example only (grey; used only when "Fill example values" is Yes)
B6: Your gross yearly income | D6: € | E6: Type 3 · your figure · Your own figure. In the app it is pre-filled from Your finances: income. Allowed: €15,000 to €2,500,000 · steps of €1,000 | F6: 60000 | G6: =IF(ISBLANK(C6),IF(Fill_Example="Yes",F6,""),C6)
B7: Partner's gross yearly income | D7: € | E7: Type 3 · your figure · Your own figure. In the app it is pre-filled from Your finances: partner's income. Allowed: €0 to €2,500,000 · steps of €1,000 | F7: 0 | G7: =IF(ISBLANK(C7),IF(Fill_Example="Yes",F7,""),C7)
B8: Deposit saved | D8: € | E8: Type 3 · your figure · Your own figure. In the app it is pre-filled from Plan: home goal's amount saved. Allowed: €0 to €2,000,000 · steps of €1,000 | F8: 25000 | G8: =IF(ISBLANK(C8),IF(Fill_Example="Yes",F8,""),C8)
B9: First-time buyer? | D9: Yes / No | E9: Type 3 · your figure · Your own figure. In the app it is pre-filled from Your finances: home status (owner = No). Allowed: Yes or No | F9: Yes | G9: =IF(ISBLANK(C9),IF(Fill_Example="Yes",F9,""),C9)
B10: Mortgage interest rate | D10: % | E10: ="Type 2 · your figure · Your own rate (your statement shows it; typing it is fine, no upload needed). "&IF(ISNUMBER(Suggest_Mortgage_Rate),"Suggested: "&TEXT(Suggest_Mortgage_Rate,"0.00%")&" · "&Suggest_Mortgage_Rate_Label&". ","No suggestion. ")&"Enter your own figure."&" Allowed: 1% to 8% · steps of 0.05%" -> Type 2 · your figure · Your own rate (your statement shows it; typing it is fine, no upload needed). Suggested: 3.48% · Central Bank of Ireland: average rate on new mortgages, Jul 2026. Enter your own figure. Allowed: 1% to 8% · steps of 0.05% | F10: =IF(ISNUMBER(Suggest_Mortgage_Rate),Suggest_Mortgage_Rate,"") -> 0.0348 | G10: =IF(ISBLANK(C10),IF(Fill_Example="Yes",F10,""),C10)
B11: Mortgage term | D11: years | E11: Type 3 · your figure · Your own figure. Allowed: 10 to 35 · steps of 1 | F11: 30 | G11: =IF(AND(ISNUMBER(C11),N(C11)<10),"",IF(ISBLANK(C11),IF(Fill_Example="Yes",F11,""),C11))
B12: Legal and other buying fees | D12: € | E12: ="Type 2 · optional · Legal and survey fees (stamp duty is added for you). "&IF(ISNUMBER(Suggest_Buying_Fees),"Suggested: "&TEXT(Suggest_Buying_Fees,"€#,##0")&" · "&Suggest_Buying_Fees_Label&". ","No suggestion. ")&"Leave blank to count €0."&" Allowed: €0 to €10,000 · steps of €100" -> Type 2 · optional · Legal and survey fees (stamp duty is added for you). No suggestion. Leave blank to count €0. Allowed: €0 to €10,000 · steps of €100 | F12: =IF(ISNUMBER(Suggest_Buying_Fees),Suggest_Buying_Fees,"") | G12: =IF(ISBLANK(C12),IF(AND(Fill_Example="Yes",ISNUMBER(F12)),F12,0),C12) -> 0
B13: Years until you buy (for the plan) | D13: years | E13: Type 3 · your figure · Your own figure. Allowed: 1 to 30 · steps of 1 | F13: 3 | G13: =IF(ISBLANK(C13),IF(Fill_Example="Yes",F13,""),C13)
B14: What if: save extra towards the deposit | D14: € | E14: Type 3 · optional · Optional: leave blank for none. Allowed: €0 to €500,000 · steps of €1,000 | F14: 0 | G14: =IF(ISBLANK(C14),F14,C14) -> 0
B16: RESULTS | C16: Result | D16: Shown as | E16: Formula
B17: Homes up to about | C17: =IF(Need_1<>"",Need_1,MIN(Price_By_Deposit,Price_By_Income)) -> Choose your gross yearly income to see this | D17: € | E17: ƒx =MIN(Price_By_Deposit,Price_By_Income)
B18: Most you could borrow | C18: =IF(Need_1<>"",Need_1,MIN(Borrow_By_Income,LTV_Max*Home_Price)) -> Choose your gross yearly income to see this | D18: € | E18: ƒx =MIN(Borrow_By_Income,LTV_Max*Home_Price)
B19: Monthly repayment (illustrative) | C19: =IF(Need_2<>"",Need_2,PMT(Interest_Rate/12,Term_Years*12,-Max_Loan)) -> Choose your gross yearly income to see this | D19: € | E19: ƒx =PMT(Interest_Rate/12,Term_Years*12,-Max_Loan)
B20: Stamp duty on that price (paid from your deposit) | C20: =IF(Need_1<>"",Need_1,SD_Rate_1*MIN(Home_Price,SD_Band_1)+SD_Rate_2*MAX(0,MIN(Home_Price,SD_Band_2)-SD_Band_1)+SD_Rate_3*MAX(0,Home_Price-SD_Band_2)) -> Choose your gross yearly income to see this | D20: € | E20: ƒx =SD_Rate_1*MIN(Home_Price,SD_Band_1)+SD_Rate_2*MAX(0,MIN(Home_Price,SD_Band_2)-SD_Band_1)+SD_Rate_3*MAX(0,Home_Price-SD_Band_2)
B21: Borrowing allowed by income | C21: =IF(Need_3<>"",Need_3,(Income+Partner_Income)*Income_Multiple) -> Choose your gross yearly income to see this | D21: € | E21: ƒx =(Income+Partner_Income)*Income_Multiple
B22: Income multiple used | C22: =IF(Need_4<>"",Need_4,IF(First_Time_Buyer="Yes",LTI_FTB,LTI_SSB)) -> Choose your first-time buyer answer to see this | D22: × income | E22: ƒx =IF(First_Time_Buyer="Yes",LTI_FTB,LTI_SSB)
B23: Your deposit (incl. what-if extra) | C23: =IF(Need_5<>"",Need_5,Deposit+Extra_Deposit) -> Choose your deposit saved to see this | D23: € | E23: ƒx =Deposit+Extra_Deposit
B24: Deposit left for the price after fees | C24: =IF(Need_6<>"",Need_6,MAX(0,Total_Deposit-Buying_Fees)) -> Choose your deposit saved to see this | D24: € | E24: ƒx =MAX(0,Total_Deposit-Buying_Fees)
B25: Deposit + stamp duty needed for a €1m home | C25: =(1-LTV_Max+SD_Rate_1)*SD_Band_1 -> 110000 | D25: € | E25: ƒx =(1-LTV_Max+SD_Rate_1)*SD_Band_1
B26: Deposit + stamp duty needed for a €1.5m home | C26: =Cash_At_Band_1+(1-LTV_Max+SD_Rate_2)*(SD_Band_2-SD_Band_1) -> 170000 | D26: € | E26: ƒx =Cash_At_Band_1+(1-LTV_Max+SD_Rate_2)*(SD_Band_2-SD_Band_1)
B27: Price your deposit allows (10% deposit + stamp duty) | C27: =IF(Need_6<>"",Need_6,IF(Cash_For_Price<=Cash_At_Band_1,Cash_For_Price/(1-LTV_Max+SD_Rate_1),IF(Cash_For_Price<=Cash_At_Band_2,SD_Band_1+(Cash_For_Price-Cash_At_Band_1)/(1-LTV_Max+SD_Rate_2),SD_Band_2+(Cash_For_Price-Cash_At_Band_2)/(1-LTV_Max+SD_Rate_3)))) -> Choose your deposit saved to see this | D27: € | E27: ƒx =IF(Cash_For_Price<=Cash_At_Band_1,Cash_For_Price/(1-LTV_Max+SD_Rate_1),IF(Cash_For_Price<=Cash_At_Band_2,SD_Band_1+(Cash_For_Price-Cash_At_Band_1)/(1-LTV_Max+SD_Rate_2),SD_Band_2+(Cash_For_Price-Cash_At_Band_2)/(1-LTV_Max+SD_Rate_3)))
B28: Income limit + deposit left after fees | C28: =IF(Need_1<>"",Need_1,Borrow_By_Income+Cash_For_Price) -> Choose your gross yearly income to see this | D28: € | E28: ƒx =Borrow_By_Income+Cash_For_Price
B29: Price your income allows (loan + deposit, after stamp duty) | C29: =IF(Need_1<>"",Need_1,IF(Income_Cash<=(1+SD_Rate_1)*SD_Band_1,Income_Cash/(1+SD_Rate_1),IF(Income_Cash<=(1+SD_Rate_1)*SD_Band_1+(1+SD_Rate_2)*(SD_Band_2-SD_Band_1),SD_Band_1+(Income_Cash-(1+SD_Rate_1)*SD_Band_1)/(1+SD_Rate_2),SD_Band_2+(Income_Cash-(1+SD_Rate_1)*SD_Band_1-(1+SD_Rate_2)*(SD_Band_2-SD_Band_1))/(1+SD_Rate_3)))) -> Choose your gross yearly income to see this | D29: € | E29: ƒx =IF(Income_Cash<=(1+SD_Rate_1)*SD_Band_1,Income_Cash/(1+SD_Rate_1),IF(Income_Cash<=(1+SD_Rate_1)*SD_Band_1+(1+SD_Rate_2)*(SD_Band_2-SD_Band_1),SD_Band_1+(Income_Cash-(1+SD_Rate_1)*SD_Band_1)/(1+SD_Rate_2),SD_Band_2+(Income_Cash-(1+SD_Rate_1)*SD_Band_1-(1+SD_Rate_2)*(SD_Band_2-SD_Band_1))/(1+SD_Rate_3)))
B30: What sets the limit | C30: =IF(Need_1<>"",Need_1,IF(Price_By_Deposit<Price_By_Income,"Your deposit","Your income")) -> Choose your gross yearly income to see this | E30: ƒx =IF(Price_By_Deposit<Price_By_Income,"Your deposit","Your income")
B32: HOW IT WORKS
B33: ="• Income limit = combined gross income "&"× "&LTI_FTB&" (first-time buyer)"&" or "&"× "&LTI_SSB&" (everyone else)"&". The loan can also be at most "&TEXT(LTV_Max,"0%")&" of the price." -> • Income limit = combined gross income × 4 (first-time buyer) or × 3.5 (everyone else). The loan can also be at most 90% of the price.
B34: • Your deposit must pay 10% of the price, the stamp duty (1% up to €1m, 2% on €1m–€1.5m, 6% above) and the buying fees. So the price is the lower of: what the deposit allows (10% + stamp duty) and what income + deposit allow (price + stamp duty). Both are solved exactly, band by band.
B35: • Repayment = standard annuity PMT at rate ÷ 12 over the term.
B36: Edge rules and validation:
B37: • First-time buyer is a Yes/No choice.
B38: • When both limits are equal the text says the income sets the limit.
B39: • Lenders can lend above these limits for a small share of loans each year, so some buyers get an exception. Your lender decides.
B40: • At 0% interest Excel's PMT/NPER/FV give amount ÷ months, so no special case is needed in Excel; in code use payment = amount / months.
B42: ADD TO MY PLAN (what this calculator sends to the plan)
B43: Goal | C43: ="Buy a home (deposit goal)" -> Buy a home (deposit goal) | E43: ƒx ="Buy a home (deposit goal)"
B44: Amount (today's money): 10% deposit + stamp duty + fees | C44: =IF(Need_1<>"",Need_1,ROUND(Home_Price*Min_Deposit_Pct+Stamp_Duty+Buying_Fees,0)) -> Choose your gross yearly income to see this | E44: ƒx =ROUND(Home_Price*Min_Deposit_Pct+Stamp_Duty+Buying_Fees,0)
...

Sheet C02 Mortgage repayment
B1: C02 · Monthly mortgage repayment | E1: Category: Home & Mortgage · prototype id: repayment
B2: Question it answers: What would my monthly repayment be? | E2: =IF(Fill_Example="Yes","Example values are ON (README): grey Example only figures fill blank inputs.","Blank template: fill the yellow inputs (or switch on example values on the README).") -> Blank template: fill the yellow inputs (or switch on example values on the README).
B3: Works out the monthly repayment, how long until the mortgage is paid off and the total interest; and what a rate change would do.
B5: FROM YOUR STATEMENT (filled automatically by the document reader)
B6: Document: Mortgage statement (annual statement of account) or offer letter. Blank = no statement uploaded, or the figure is not on it. Grey-blue cells are filled by the reader (you can type here to test).
B7: Outstanding balance | D7: € | E7: Allowed: €0 to €10,000,000 | G7: Reader field: see note
B8: Interest rate | D8: % | E8: Allowed: 0% to 15% | G8: Reader field: see note
B9: Term remaining | D9: years | E9: Allowed: 0 to 40 | G9: Reader field: see note
B10: Monthly repayment | D10: € | E10: Allowed: €0 to €100,000 | G10: Reader field: see note
B11: Statement date | D11: date | E11: Allowed: a date (dd/mm/yyyy) | G11: Reader field: see note
B13: OR TYPE IT YOURSELF | C13: Your figure | D13: Unit | E13: Allowed | F13: Example only (grey; used only when "Fill example values" is Yes)
B14: Mortgage amount | D14: € | E14: Type 3 · your figure · Your own figure. In the app it is pre-filled from Your finances / mortgage statement: balance. Allowed: €50,000 to €10,000,000 · steps of €1,000 | F14: 300000 | G14: =IF(ISBLANK(C14),IF(Fill_Example="Yes",F14,""),C14)
B15: Interest rate | D15: % | E15: ="Type 2 · your figure · Your own rate (your statement shows it; typing it is fine, no upload needed). "&IF(ISNUMBER(Suggest_Mortgage_Rate),"Suggested: "&TEXT(Suggest_Mortgage_Rate,"0.00%")&" · "&Suggest_Mortgage_Rate_Label&". ","No suggestion. ")&"Enter your own figure."&" In the app it is pre-filled from Your finances / mortgage statement: rate. Enter your own figure. Allowed: 1% to 8% · steps of 0.05%" -> Type 2 · your figure · Your own rate (your statement shows it; typing it is fine, no upload needed). Suggested: 3.48% · Central Bank of Ireland: average rate on new mortgages, Jul 2026. Enter your own figure. In the app it is pre-filled from Your finances / mortgage statement: rate. Enter your own figure. Allowed: 1% to 8% · steps of 0.05% | F15: =IF(ISNUMBER(Suggest_Mortgage_Rate),Suggest_Mortgage_Rate,"") -> 0.0348 | G15: =IF(ISBLANK(C15),IF(Fill_Example="Yes",F15,""),C15)
B16: Term | D16: years | E16: Type 3 · your figure · Your own figure. In the app it is pre-filled from Years left (25 if not given). Allowed: 5 to 35 · steps of 1 | F16: 30 | G16: =IF(AND(ISNUMBER(C16),N(C16)<5),"",IF(ISBLANK(C16),IF(Fill_Example="Yes",F16,""),C16))
B17: Your actual monthly repayment (optional, 0 = work it out) | D17: € | E17: Type 3 · optional · Optional: leave blank for none. Allowed: €0 to €100,000 · steps of €1 | F17: 0 | G17: =IF(ISBLANK(C17),F17,C17) -> 0
B18: Years until you buy (for the plan) | D18: years | E18: Type 3 · your figure · Your own figure. Allowed: 1 to 30 · steps of 1 | F18: 3 | G18: =IF(ISBLANK(C18),IF(Fill_Example="Yes",F18,""),C18)
B19: What if: rates change by | D19: % | E19: Type 3 · optional · Optional: leave blank for none. Allowed: -2% to 3% · steps of 0.25% | F19: 0 | G19: =IF(ISBLANK(C19),F19,C19) -> 0
B21: FIGURE USED (statement figure if present, else your figure)
B22: Mortgage amount | C22: =IF(ISBLANK(Stmt_Balance),Loan_Amount,Stmt_Balance) | D22: =IF(ISBLANK(Stmt_Balance),"Your figure","From your statement") -> Your figure | E22: ƒx =IF(ISBLANK(Stmt_Balance),Loan_Amount,Stmt_Balance)
B23: Interest rate | C23: =IF(ISBLANK(Stmt_Rate),Interest_Rate,Stmt_Rate) | D23: =IF(ISBLANK(Stmt_Rate),"Your figure","From your statement") -> Your figure | E23: ƒx =IF(ISBLANK(Stmt_Rate),Interest_Rate,Stmt_Rate)
B24: Term | C24: =IF(ISBLANK(Stmt_Term),Term_Years,Stmt_Term) | D24: =IF(ISBLANK(Stmt_Term),"Your figure","From your statement") -> Your figure | E24: ƒx =IF(ISBLANK(Stmt_Term),Term_Years,Stmt_Term)
B25: Actual monthly repayment (0 = work it out) | C25: =IF(ISBLANK(Stmt_Repayment),Actual_Repayment,Stmt_Repayment) -> 0 | D25: =IF(ISBLANK(Stmt_Repayment),"Your figure","From your statement") -> Your figure | E25: ƒx =IF(ISBLANK(Stmt_Repayment),Actual_Repayment,Stmt_Repayment)
B26: Statement date check | C26: =IF(ISBLANK(Stmt_Statement_Date),"",IF(TODAY()-Stmt_Statement_Date>Statement_Max_Age_Days,"Needs a look: statement is more than 12 months old","Up to date")) | E26: ƒx =IF(ISBLANK(Stmt_Statement_Date),"",IF(TODAY()-Stmt_Statement_Date>Statement_Max_Age_Days,"Needs a look: statement is more than 12 months old","Up to date"))
B28: RESULTS | C28: Result | D28: Shown as | E28: Formula
B29: Monthly repayment | C29: =IF(Need_1<>"",Need_1,IF(Used_Actual_Repayment>0,Used_Actual_Repayment,Formula_Repayment)) -> Choose your mortgage amount to see this | D29: € | E29: ƒx =IF(Used_Actual_Repayment>0,Used_Actual_Repayment,Formula_Repayment)
B30: Mortgage free in (months) | C30: =IF(Need_1<>"",Need_1,IF(Monthly_Repayment<=Used_Loan_Amount*Monthly_Rate,"Never",ROUNDUP(ROUND(NPER(Monthly_Rate,-Monthly_Repayment,Used_Loan_Amount),6),0))) -> Choose your mortgage amount to see this | D30: =IF(Need_1<>"",Need_1,IF(Months_To_Pay="Never","Never at this repayment",IF(Months_To_Pay>Cap_Months,"Over 100 years",IF(INT(Months_To_Pay/12)=0,MOD(Months_To_Pay,12)&IF(MOD(Months_To_Pay,12)=1," month"," months"),INT(Months_To_Pay/12)&IF(INT(Months_To_Pay/12)=1," year"," years")&IF(MOD(Months_To_Pay,12)=0,""," "&MOD(Months_To_Pay,12)&IF(MOD(Months_To_Pay,12)=1," month"," months")))))) -> Choose your mortgage amount to see this | E30: ƒx =IF(Monthly_Repayment<=Used_Loan_Amount*Monthly_Rate,"Never",ROUNDUP(ROUND(NPER(Monthly_Rate,-Monthly_Repayment,Used_Loan_Amount),6),0))
B31: Total interest | C31: =IF(Need_1<>"",Need_1,IF(Months_To_Pay="Never","—",Monthly_Repayment*(Months_To_Pay-1)+Final_Payment-Used_Loan_Amount)) -> Choose your mortgage amount to see this | D31: € | E31: ƒx =IF(Months_To_Pay="Never","—",Monthly_Repayment*(Months_To_Pay-1)+Final_Payment-Used_Loan_Amount)
B32: Total repaid | C32: =IF(Need_1<>"",Need_1,IF(Months_To_Pay="Never","—",Used_Loan_Amount+Total_Interest)) -> Choose your mortgage amount to see this | D32: € | E32: ƒx =IF(Months_To_Pay="Never","—",Used_Loan_Amount+Total_Interest)
B33: Monthly interest rate | C33: =IF(Need_2<>"",Need_2,Used_Interest_Rate/12) -> Choose your mortgage rate to see this | E33: ƒx =Used_Interest_Rate/12
B34: Repayment by formula (standard annuity) | C34: =IF(Need_3<>"",Need_3,PMT(Monthly_Rate,Used_Term_Years*12,-Used_Loan_Amount)) -> Choose your mortgage amount to see this | D34: € | E34: ƒx =PMT(Monthly_Rate,Used_Term_Years*12,-Used_Loan_Amount)
B35: Last (part) payment | C35: =IF(Need_1<>"",Need_1,IF(Months_To_Pay="Never","—",-FV(Monthly_Rate,Months_To_Pay-1,-Monthly_Repayment,Used_Loan_Amount)*(1+Monthly_Rate))) -> Choose your mortgage amount to see this | D35: € | E35: ƒx =IF(Months_To_Pay="Never","—",-FV(Monthly_Rate,Months_To_Pay-1,-Monthly_Repayment,Used_Loan_Amount)*(1+Monthly_Rate)) (balance left before the last month, plus that month's interest)
B36: What if: new rate (never below 0%) | C36: =IF(Need_2<>"",Need_2,MAX(0,Used_Interest_Rate+Rate_Change)) -> Choose your mortgage rate to see this | D36: % | E36: ƒx =MAX(0,Used_Interest_Rate+Rate_Change)
B37: What if: monthly repayment | C37: =IF(Need_1<>"",Need_1,Monthly_Repayment+PMT(New_Rate/12,Used_Term_Years*12,-Used_Loan_Amount)-Formula_Repayment) -> Choose your mortgage amount to see this | D37: € | E37: ƒx =Monthly_Repayment+PMT(New_Rate/12,Used_Term_Years*12,-Used_Loan_Amount)-Formula_Repayment
B38: What if: change over a year | C38: =IF(Need_1<>"",Need_1,(Repayment_If_Changed-Monthly_Repayment)*12) -> Choose your mortgage amount to see this | D38: € | E38: ƒx =(Repayment_If_Changed-Monthly_Repayment)*12
B40: HOW IT WORKS
B41: • Repayment = PMT(rate ÷ 12, years × 12, −amount), the standard repayment-mortgage formula; your stated repayment replaces it if you give one.
B42: • Months to pay off = NPER(rate ÷ 12, −repayment, amount), rounded up. Total interest = all full payments + the last part payment − the amount (exact, as a lender's schedule).
B43: • What if: the stated repayment moves by the same amount as the formula repayment would: repayment + PMT(new rate) − PMT(current rate). The new rate is floored at 0%.
B44: Edge rules and validation:
B45: • If the payment is at or below the first month's interest the balance never falls: show "Never at this repayment" and leave total interest blank ("—").
...

Sheet C03 Deposit
B1: C03 · Deposit calculator | E1: Category: Home & Mortgage · prototype id: deposit
B2: Question it answers: How long until I have my deposit? | E2: =IF(Fill_Example="Yes","Example values are ON (README): grey Example only figures fill blank inputs.","Blank template: fill the yellow inputs (or switch on example values on the README).") -> Blank template: fill the yellow inputs (or switch on example values on the README).
B3: Works out the deposit, stamp duty and fees you need and how many months of saving it takes.
B5: INPUTS | C5: Your figure | D5: Unit | E5: Allowed | F5: Example only (grey; used only when "Fill example values" is Yes)
B6: Home price | D6: € | E6: Type 3 · your figure · Your own figure. Allowed: €100,000 to €10,000,000 · steps of €5,000 | F6: 350000 | G6: =IF(ISBLANK(C6),IF(Fill_Example="Yes",F6,""),C6)
B7: Deposit needed | D7: % | E7: ="Type 3 · your figure · Your own figure. Allowed: 10% to 30% · steps of 1% · the Central Bank "&"minimum is "&TEXT(Min_Deposit_Pct,"0%")&" ("&TEXT(LTV_Max,"0%")&" LTV)" -> Type 3 · your figure · Your own figure. Allowed: 10% to 30% · steps of 1% · the Central Bank minimum is 10% (90% LTV) | F7: 0.1 | G7: =IF(ISBLANK(C7),IF(Fill_Example="Yes",F7,""),C7)
B8: Legal and other buying fees | D8: € | E8: ="Type 2 · optional · Legal and survey fees (stamp duty is added for you). "&IF(ISNUMBER(Suggest_Buying_Fees),"Suggested: "&TEXT(Suggest_Buying_Fees,"€#,##0")&" · "&Suggest_Buying_Fees_Label&". ","No suggestion. ")&"Leave blank to count €0."&" Allowed: €0 to €10,000 · steps of €100" -> Type 2 · optional · Legal and survey fees (stamp duty is added for you). No suggestion. Leave blank to count €0. Allowed: €0 to €10,000 · steps of €100 | F8: =IF(ISNUMBER(Suggest_Buying_Fees),Suggest_Buying_Fees,"") | G8: =IF(ISBLANK(C8),IF(AND(Fill_Example="Yes",ISNUMBER(F8)),F8,0),C8) -> 0
B9: Saved so far | D9: € | E9: Type 3 · your figure · Your own figure. In the app it is pre-filled from Plan: home goal's amount saved. Allowed: €0 to €2,000,000 · steps of €500 | F9: 12000 | G9: =IF(ISBLANK(C9),IF(Fill_Example="Yes",F9,""),C9)
B10: Monthly saving | D10: € | E10: Type 3 · your figure · Your own figure. Allowed: €50 to €50,000 · steps of €50 | F10: 800 | G10: =IF(AND(ISNUMBER(C10),N(C10)<50),"",IF(ISBLANK(C10),IF(Fill_Example="Yes",F10,""),C10))
B11: What if: save extra each month | D11: € | E11: Type 3 · optional · Optional: leave blank for none. Allowed: €0 to €15,000 · steps of €50 | F11: 0 | G11: =IF(ISBLANK(C11),F11,C11) -> 0
B13: RESULTS | C13: Result | D13: Shown as | E13: Formula
B14: Time to your deposit (months) | C14: =IF(Need_1<>"",Need_1,IF(Still_To_Save=0,0,ROUNDUP(Still_To_Save/(Monthly_Saving+Extra_Saving),0))) -> Choose your home price to see this | D14: =IF(Need_1<>"",Need_1,IF(Months_To_Deposit=0,"You have your deposit",IF(INT(Months_To_Deposit/12)=0,MOD(Months_To_Deposit,12)&IF(MOD(Months_To_Deposit,12)=1," month"," months"),INT(Months_To_Deposit/12)&IF(INT(Months_To_Deposit/12)=1," year"," years")&IF(MOD(Months_To_Deposit,12)=0,""," "&MOD(Months_To_Deposit,12)&IF(MOD(Months_To_Deposit,12)=1," month"," months"))))) -> Choose your home price to see this | E14: ƒx =IF(Still_To_Save=0,0,ROUNDUP(Still_To_Save/(Monthly_Saving+Extra_Saving),0))
B15: Total you need (deposit + stamp duty + fees) | C15: =IF(Need_2<>"",Need_2,Deposit_Needed+Stamp_Duty+Buying_Fees) -> Choose your home price to see this | D15: € | E15: ƒx =Deposit_Needed+Stamp_Duty+Buying_Fees
B16: Still to save | C16: =IF(Need_3<>"",Need_3,MAX(0,Total_Needed-Saved)) -> Choose your home price to see this | D16: € | E16: ƒx =MAX(0,Total_Needed-Saved)
B17: Deposit | C17: =IF(Need_4<>"",Need_4,Home_Price*Deposit_Pct) -> Choose your home price to see this | D17: € | E17: ƒx =Home_Price*Deposit_Pct
B18: Stamp duty | C18: =IF(Need_5<>"",Need_5,SD_Rate_1*MIN(Home_Price,SD_Band_1)+SD_Rate_2*MAX(0,MIN(Home_Price,SD_Band_2)-SD_Band_1)+SD_Rate_3*MAX(0,Home_Price-SD_Band_2)) -> Choose your home price to see this | D18: € | E18: ƒx =SD_Rate_1*MIN(Home_Price,SD_Band_1)+SD_Rate_2*MAX(0,MIN(Home_Price,SD_Band_2)-SD_Band_1)+SD_Rate_3*MAX(0,Home_Price-SD_Band_2)
B20: HOW IT WORKS
B21: • Deposit = price × deposit %. Stamp duty = 1% up to €1m, 2% on €1m–€1.5m, 6% above. Total = deposit + stamp duty + fees.
B22: • Months = still to save ÷ monthly saving (incl. the what-if extra), rounded up. No interest and no house-price growth are assumed.
B23: Edge rules and validation:
B24: ="• Deposit % "&"starts at "&TEXT(Min_Deposit_Pct,"0%")&", the Central Bank minimum ("&TEXT(LTV_Max,"0%")&" loan-to-value)." -> • Deposit % starts at 10%, the Central Bank minimum (90% loan-to-value).
B25: • Nothing left to save shows "You have your deposit".
B26: • Monthly saving must be at least €50, so there is no divide by zero.
B28: ADD TO MY PLAN (what this calculator sends to the plan)
B29: Goal | C29: ="Home deposit" -> Home deposit | E29: ƒx ="Home deposit"
B30: Amount (today's money): deposit + stamp duty + fees | C30: =IF(Need_2<>"",Need_2,ROUND(Total_Needed,0)) -> Choose your home price to see this | E30: ƒx =ROUND(Total_Needed,0)
B31: Already saved | C31: =IF(Need_6<>"",Need_6,Saved) -> Choose your saved so far to see this | E31: ƒx =Saved
B32: In (years) | C32: =IF(Need_1<>"",Need_1,MAX(1,ROUNDUP(Months_To_Deposit/12,0))) -> Choose your home price to see this | E32: ƒx =MAX(1,ROUNDUP(Months_To_Deposit/12,0))
B34: CHOICES STILL NEEDED (helper rows: blank = all inputs a result needs are filled)
B35: Needs: buying fees, deposit %, home price, monthly saving, saved so far | C35: =IF(Home_Price="","Choose your home price to see this",IF(Deposit_Pct="","Choose your deposit % to see this",IF(Buying_Fees="","Choose your buying fees to see this",IF(Saved="","Choose your saved so far to see this",IF(Monthly_Saving="","Choose your monthly saving to see this",""))))) -> Choose your home price to see this
B36: Needs: buying fees, deposit %, home price | C36: =IF(Home_Price="","Choose your home price to see this",IF(Deposit_Pct="","Choose your deposit % to see this",IF(Buying_Fees="","Choose your buying fees to see this",""))) -> Choose your home price to see this
B37: Needs: buying fees, deposit %, home price, saved so far | C37: =IF(Home_Price="","Choose your home price to see this",IF(Deposit_Pct="","Choose your deposit % to see this",IF(Buying_Fees="","Choose your buying fees to see this",IF(Saved="","Choose your saved so far to see this","")))) -> Choose your home price to see this
B38: Needs: deposit %, home price | C38: =IF(Home_Price="","Choose your home price to see this",IF(Deposit_Pct="","Choose your deposit % to see this","")) -> Choose your home price to see this
B39: Needs: home price | C39: =IF(Home_Price="","Choose your home price to see this","") -> Choose your home price to see this
B40: Needs: saved so far | C40: =IF(Saved="","Choose your saved so far to see this","") -> Choose your saved so far to see this
B42: Note: stamp duty is worked out on the price shown; for a new home it is charged on the price excluding VAT, and Help to Buy is not included.

Sheet C04 Mortgage overpayment
B1: C04 · Mortgage overpayment | E1: Category: Home & Mortgage · prototype id: overpay
B2: Question it answers: What if I paid a little extra each month? | E2: =IF(Fill_Example="Yes","Example values are ON (README): grey Example only figures fill blank inputs.","Blank template: fill the yellow inputs (or switch on example values on the README).") -> Blank template: fill the yellow inputs (or switch on example values on the README).
B3: Compares paying off the mortgage at your repayment with paying a little extra each month: time and interest saved.
B5: FROM YOUR STATEMENT (filled automatically by the document reader)
B6: Document: Mortgage statement (annual statement of account) or offer letter. Blank = no statement uploaded, or the figure is not on it. Grey-blue cells are filled by the reader (you can type here to test).
B7: Outstanding balance | D7: € | E7: Allowed: €0 to €10,000,000 | G7: Reader field: see note
B8: Interest rate | D8: % | E8: Allowed: 0% to 15% | G8: Reader field: see note
B9: Term remaining | D9: years | E9: Allowed: 0 to 40 | G9: Reader field: see note
B10: Monthly repayment | D10: € | E10: Allowed: €0 to €100,000 | G10: Reader field: see note
B11: Statement date | D11: date | E11: Allowed: a date (dd/mm/yyyy) | G11: Reader field: see note
B13: OR TYPE IT YOURSELF | C13: Your figure | D13: Unit | E13: Allowed | F13: Example only (grey; used only when "Fill example values" is Yes)
B14: Mortgage balance | D14: € | E14: Type 3 · your figure · Your own figure. In the app it is pre-filled from Your finances / statement: balance. Allowed: €20,000 to €10,000,000 · steps of €1,000 | F14: 250000 | G14: =IF(ISBLANK(C14),IF(Fill_Example="Yes",F14,""),C14)
B15: Interest rate | D15: % | E15: ="Type 2 · your figure · Your own rate (your statement shows it; typing it is fine, no upload needed). "&IF(ISNUMBER(Suggest_Mortgage_Rate),"Suggested: "&TEXT(Suggest_Mortgage_Rate,"0.00%")&" · "&Suggest_Mortgage_Rate_Label&". ","No suggestion. ")&"Enter your own figure."&" In the app it is pre-filled from Your finances / statement: rate. Enter your own figure. Allowed: 1% to 8% · steps of 0.05%" -> Type 2 · your figure · Your own rate (your statement shows it; typing it is fine, no upload needed). Suggested: 3.48% · Central Bank of Ireland: average rate on new mortgages, Jul 2026. Enter your own figure. In the app it is pre-filled from Your finances / statement: rate. Enter your own figure. Allowed: 1% to 8% · steps of 0.05% | F15: =IF(ISNUMBER(Suggest_Mortgage_Rate),Suggest_Mortgage_Rate,"") -> 0.0348 | G15: =IF(ISBLANK(C15),IF(Fill_Example="Yes",F15,""),C15)
B16: Years left | D16: years | E16: Type 3 · your figure · Your own figure. In the app it is pre-filled from Years left (25 if not given). Allowed: 3 to 35 · steps of 1 | F16: 25 | G16: =IF(AND(ISNUMBER(C16),N(C16)<3),"",IF(ISBLANK(C16),IF(Fill_Example="Yes",F16,""),C16))
B17: Extra each month | D17: € | E17: Type 3 · your figure · Your own figure. Allowed: €0 to €20,000 · steps of €25 | F17: 200 | G17: =IF(ISBLANK(C17),IF(Fill_Example="Yes",F17,""),C17)
B18: Your actual monthly repayment (optional, 0 = work it out) | D18: € | E18: Type 3 · optional · Optional: leave blank for none. Allowed: €0 to €100,000 · steps of €1 | F18: 0 | G18: =IF(ISBLANK(C18),F18,C18) -> 0
B20: FIGURE USED (statement figure if present, else your figure)
B21: Mortgage balance | C21: =IF(ISBLANK(Stmt_Balance),Mortgage_Balance,Stmt_Balance) | D21: =IF(ISBLANK(Stmt_Balance),"Your figure","From your statement") -> Your figure | E21: ƒx =IF(ISBLANK(Stmt_Balance),Mortgage_Balance,Stmt_Balance)
B22: Interest rate | C22: =IF(ISBLANK(Stmt_Rate),Interest_Rate,Stmt_Rate) | D22: =IF(ISBLANK(Stmt_Rate),"Your figure","From your statement") -> Your figure | E22: ƒx =IF(ISBLANK(Stmt_Rate),Interest_Rate,Stmt_Rate)
B23: Years left | C23: =IF(ISBLANK(Stmt_Term),Years_Left,Stmt_Term) | D23: =IF(ISBLANK(Stmt_Term),"Your figure","From your statement") -> Your figure | E23: ƒx =IF(ISBLANK(Stmt_Term),Years_Left,Stmt_Term)
B24: Actual monthly repayment (0 = work it out) | C24: =IF(ISBLANK(Stmt_Repayment),Actual_Repayment,Stmt_Repayment) -> 0 | D24: =IF(ISBLANK(Stmt_Repayment),"Your figure","From your statement") -> Your figure | E24: ƒx =IF(ISBLANK(Stmt_Repayment),Actual_Repayment,Stmt_Repayment)
B25: Statement date check | C25: =IF(ISBLANK(Stmt_Statement_Date),"",IF(TODAY()-Stmt_Statement_Date>Statement_Max_Age_Days,"Needs a look: statement is more than 12 months old","Up to date")) | E25: ƒx =IF(ISBLANK(Stmt_Statement_Date),"",IF(TODAY()-Stmt_Statement_Date>Statement_Max_Age_Days,"Needs a look: statement is more than 12 months old","Up to date"))
B27: RESULTS | C27: Result | D27: Shown as | E27: Formula
B28: Mortgage free sooner by (months) | C28: =IF(Need_1<>"",Need_1,IF(OR(Months_Now="Never",Months_With_Extra="Never"),"—",Months_Now-Months_With_Extra)) -> Choose your extra each month to see this | D28: =IF(Need_1<>"",Need_1,IF(Months_Sooner="—","—",IF(Months_Sooner=0,"No change",IF(INT(Months_Sooner/12)=0,MOD(Months_Sooner,12)&IF(MOD(Months_Sooner,12)=1," month"," months"),INT(Months_Sooner/12)&IF(INT(Months_Sooner/12)=1," year"," years")&IF(MOD(Months_Sooner,12)=0,""," "&MOD(Months_Sooner,12)&IF(MOD(Months_Sooner,12)=1," month"," months")))))) -> Choose your extra each month to see this | E28: ƒx =IF(OR(Months_Now="Never",Months_With_Extra="Never"),"—",Months_Now-Months_With_Extra)
B29: Interest saved | C29: =IF(Need_1<>"",Need_1,IF(OR(Months_Now="Never",Months_With_Extra="Never"),"—",Interest_Now-Interest_With_Extra)) -> Choose your extra each month to see this | D29: € | E29: ƒx =IF(OR(Months_Now="Never",Months_With_Extra="Never"),"—",Interest_Now-Interest_With_Extra)
B30: Mortgage free now in (months) | C30: =IF(Need_2<>"",Need_2,IF(Repayment_Now<=Used_Mortgage_Balance*Monthly_Rate,"Never",ROUNDUP(ROUND(NPER(Monthly_Rate,-Repayment_Now,Used_Mortgage_Balance),6),0))) -> Choose your mortgage balance to see this | D30: =IF(Need_2<>"",Need_2,IF(Months_Now="Never","Not at this repayment",IF(Months_Now>Cap_Months,"Over 100 years",IF(INT(Months_Now/12)=0,MOD(Months_Now,12)&IF(MOD(Months_Now,12)=1," month"," months"),INT(Months_Now/12)&IF(INT(Months_Now/12)=1," year"," years")&IF(MOD(Months_Now,12)=0,""," "&MOD(Months_Now,12)&IF(MOD(Months_Now,12)=1," month"," months")))))) -> Choose your mortgage balance to see this | E30: ƒx =IF(Repayment_Now<=Used_Mortgage_Balance*Monthly_Rate,"Never",ROUNDUP(ROUND(NPER(Monthly_Rate,-Repayment_Now,Used_Mortgage_Balance),6),0))
B31: With the extra (months) | C31: =IF(Need_1<>"",Need_1,IF(Repayment_With_Extra<=Used_Mortgage_Balance*Monthly_Rate,"Never",ROUNDUP(ROUND(NPER(Monthly_Rate,-Repayment_With_Extra,Used_Mortgage_Balance),6),0))) -> Choose your extra each month to see this | D31: =IF(Need_1<>"",Need_1,IF(Months_With_Extra="Never","—",IF(Months_With_Extra>Cap_Months,"Over 100 years",IF(INT(Months_With_Extra/12)=0,MOD(Months_With_Extra,12)&IF(MOD(Months_With_Extra,12)=1," month"," months"),INT(Months_With_Extra/12)&IF(INT(Months_With_Extra/12)=1," year"," years")&IF(MOD(Months_With_Extra,12)=0,""," "&MOD(Months_With_Extra,12)&IF(MOD(Months_With_Extra,12)=1," month"," months")))))) -> Choose your extra each month to see this | E31: ƒx =IF(Repayment_With_Extra<=Used_Mortgage_Balance*Monthly_Rate,"Never",ROUNDUP(ROUND(NPER(Monthly_Rate,-Repayment_With_Extra,Used_Mortgage_Balance),6),0))
B32: Monthly interest rate | C32: =IF(Need_3<>"",Need_3,Used_Interest_Rate/12) -> Choose your mortgage rate to see this | E32: ƒx =Used_Interest_Rate/12
B33: Repayment now | C33: =IF(Need_2<>"",Need_2,IF(Used_Actual_Repayment>0,Used_Actual_Repayment,PMT(Monthly_Rate,Used_Years_Left*12,-Used_Mortgage_Balance))) -> Choose your mortgage balance to see this | D33: € | E33: ƒx =IF(Used_Actual_Repayment>0,Used_Actual_Repayment,PMT(Monthly_Rate,Used_Years_Left*12,-Used_Mortgage_Balance))
B34: Repayment with the extra | C34: =IF(Need_1<>"",Need_1,Repayment_Now+Extra_Payment) -> Choose your extra each month to see this | D34: € | E34: ƒx =Repayment_Now+Extra_Payment
B35: Last (part) payment now | C35: =IF(Need_2<>"",Need_2,IF(Months_Now="Never","—",-FV(Monthly_Rate,Months_Now-1,-Repayment_Now,Used_Mortgage_Balance)*(1+Monthly_Rate))) -> Choose your mortgage balance to see this | D35: € | E35: ƒx =IF(Months_Now="Never","—",-FV(Monthly_Rate,Months_Now-1,-Repayment_Now,Used_Mortgage_Balance)*(1+Monthly_Rate))
B36: Last (part) payment with the extra | C36: =IF(Need_1<>"",Need_1,IF(Months_With_Extra="Never","—",-FV(Monthly_Rate,Months_With_Extra-1,-Repayment_With_Extra,Used_Mortgage_Balance)*(1+Monthly_Rate))) -> Choose your extra each month to see this | D36: € | E36: ƒx =IF(Months_With_Extra="Never","—",-FV(Monthly_Rate,Months_With_Extra-1,-Repayment_With_Extra,Used_Mortgage_Balance)*(1+Monthly_Rate))
B37: Total interest now | C37: =IF(Need_2<>"",Need_2,IF(Months_Now="Never","—",Repayment_Now*(Months_Now-1)+Last_Payment_Now-Used_Mortgage_Balance)) -> Choose your mortgage balance to see this | D37: € | E37: ƒx =IF(Months_Now="Never","—",Repayment_Now*(Months_Now-1)+Last_Payment_Now-Used_Mortgage_Balance)
B38: Total interest with the extra | C38: =IF(Need_1<>"",Need_1,IF(Months_With_Extra="Never","—",Repayment_With_Extra*(Months_With_Extra-1)+Last_Payment_With_Extra-Used_Mortgage_Balance)) -> Choose your extra each month to see this | D38: € | E38: ƒx =IF(Months_With_Extra="Never","—",Repayment_With_Extra*(Months_With_Extra-1)+Last_Payment_With_Extra-Used_Mortgage_Balance)
B40: HOW IT WORKS
B41: • Months to pay off = NPER(rate ÷ 12, −repayment, balance), rounded up, worked out twice: at your repayment and at repayment + extra.
B42: • Total interest = full payments + last part payment − balance. Interest saved = interest now − interest with the extra. Sooner by = the difference in months.
B43: Edge rules and validation:
B44: • If your repayment never clears the mortgage: "Not at this repayment", and "—" for sooner by and interest saved (no negative saving).
B45: • If even the extra does not clear it: "—" for "With the extra" and no goal is sent.
...

Sheet C05 Interest rate impact
B1: C05 · Interest-rate impact | E1: Category: Home & Mortgage · prototype id: ratechange
B2: Question it answers: What if my mortgage rate changed? | E2: =IF(Fill_Example="Yes","Example values are ON (README): grey Example only figures fill blank inputs.","Blank template: fill the yellow inputs (or switch on example values on the README).") -> Blank template: fill the yellow inputs (or switch on example values on the README).
B3: Shows how much your monthly repayment changes if your mortgage rate goes up or down.
B5: FROM YOUR STATEMENT (filled automatically by the document reader)
B6: Document: Mortgage statement (annual statement of account) or offer letter. Blank = no statement uploaded, or the figure is not on it. Grey-blue cells are filled by the reader (you can type here to test).
B7: Outstanding balance | D7: € | E7: Allowed: €0 to €10,000,000 | G7: Reader field: see note
B8: Interest rate | D8: % | E8: Allowed: 0% to 15% | G8: Reader field: see note
B9: Term remaining | D9: years | E9: Allowed: 0 to 40 | G9: Reader field: see note
B10: Monthly repayment | D10: € | E10: Allowed: €0 to €100,000 | G10: Reader field: see note
B11: Statement date | D11: date | E11: Allowed: a date (dd/mm/yyyy) | G11: Reader field: see note
B13: OR TYPE IT YOURSELF | C13: Your figure | D13: Unit | E13: Allowed | F13: Example only (grey; used only when "Fill example values" is Yes)
B14: Mortgage balance | D14: € | E14: Type 3 · your figure · Your own figure. In the app it is pre-filled from Your finances / statement: balance. Allowed: €50,000 to €10,000,000 · steps of €1,000 | F14: 300000 | G14: =IF(ISBLANK(C14),IF(Fill_Example="Yes",F14,""),C14)
B15: Current rate | D15: % | E15: ="Type 2 · your figure · Your own rate (your statement shows it; typing it is fine, no upload needed). "&IF(ISNUMBER(Suggest_Mortgage_Rate),"Suggested: "&TEXT(Suggest_Mortgage_Rate,"0.00%")&" · "&Suggest_Mortgage_Rate_Label&". ","No suggestion. ")&"Enter your own figure."&" In the app it is pre-filled from Your finances / statement: rate. Enter your own figure. Allowed: 1% to 8% · steps of 0.05%" -> Type 2 · your figure · Your own rate (your statement shows it; typing it is fine, no upload needed). Suggested: 3.48% · Central Bank of Ireland: average rate on new mortgages, Jul 2026. Enter your own figure. In the app it is pre-filled from Your finances / statement: rate. Enter your own figure. Allowed: 1% to 8% · steps of 0.05% | F15: =IF(ISNUMBER(Suggest_Mortgage_Rate),Suggest_Mortgage_Rate,"") -> 0.0348 | G15: =IF(ISBLANK(C15),IF(Fill_Example="Yes",F15,""),C15)
B16: Years left | D16: years | E16: Type 3 · your figure · Your own figure. In the app it is pre-filled from Years left (25 if not given). Allowed: 5 to 35 · steps of 1 | F16: 25 | G16: =IF(AND(ISNUMBER(C16),N(C16)<5),"",IF(ISBLANK(C16),IF(Fill_Example="Yes",F16,""),C16))
B17: Rate change | D17: % | E17: Type 3 · your figure · Your own figure. Allowed: -2% to 3% · steps of 0.25% | F17: 0.01 | G17: =IF(ISBLANK(C17),IF(Fill_Example="Yes",F17,""),C17)
B18: Your actual monthly repayment (optional, 0 = work it out) | D18: € | E18: Type 3 · optional · Optional: leave blank for none. Allowed: €0 to €100,000 · steps of €1 | F18: 0 | G18: =IF(ISBLANK(C18),F18,C18) -> 0
B20: FIGURE USED (statement figure if present, else your figure)
B21: Mortgage balance | C21: =IF(ISBLANK(Stmt_Balance),Mortgage_Balance,Stmt_Balance) | D21: =IF(ISBLANK(Stmt_Balance),"Your figure","From your statement") -> Your figure | E21: ƒx =IF(ISBLANK(Stmt_Balance),Mortgage_Balance,Stmt_Balance)
B22: Current rate | C22: =IF(ISBLANK(Stmt_Rate),Current_Rate,Stmt_Rate) | D22: =IF(ISBLANK(Stmt_Rate),"Your figure","From your statement") -> Your figure | E22: ƒx =IF(ISBLANK(Stmt_Rate),Current_Rate,Stmt_Rate)
B23: Years left | C23: =IF(ISBLANK(Stmt_Term),Years_Left,Stmt_Term) | D23: =IF(ISBLANK(Stmt_Term),"Your figure","From your statement") -> Your figure | E23: ƒx =IF(ISBLANK(Stmt_Term),Years_Left,Stmt_Term)
B24: Actual monthly repayment (0 = work it out) | C24: =IF(ISBLANK(Stmt_Repayment),Actual_Repayment,Stmt_Repayment) -> 0 | D24: =IF(ISBLANK(Stmt_Repayment),"Your figure","From your statement") -> Your figure | E24: ƒx =IF(ISBLANK(Stmt_Repayment),Actual_Repayment,Stmt_Repayment)
B25: Statement date check | C25: =IF(ISBLANK(Stmt_Statement_Date),"",IF(TODAY()-Stmt_Statement_Date>Statement_Max_Age_Days,"Needs a look: statement is more than 12 months old","Up to date")) | E25: ƒx =IF(ISBLANK(Stmt_Statement_Date),"",IF(TODAY()-Stmt_Statement_Date>Statement_Max_Age_Days,"Needs a look: statement is more than 12 months old","Up to date"))
B27: RESULTS | C27: Result | D27: Shown as | E27: Formula
B28: Monthly change | C28: =IF(Need_1<>"",Need_1,Repayment_After-Repayment_Now) -> Choose your rate change to see this | D28: =IF(Need_1<>"",Need_1,IF(Monthly_Change>=0,"+","−")&TEXT(ABS(Monthly_Change),"€#,##0")) -> Choose your rate change to see this | E28: ƒx =Repayment_After-Repayment_Now
B29: Repayment now | C29: =IF(Need_2<>"",Need_2,IF(Used_Actual_Repayment>0,Used_Actual_Repayment,Formula_Now)) -> Choose your mortgage balance to see this | D29: € | E29: ƒx =IF(Used_Actual_Repayment>0,Used_Actual_Repayment,Formula_Now)
B30: Repayment after the change | C30: =IF(Need_1<>"",Need_1,Repayment_Now+PMT(New_Rate/12,Used_Years_Left*12,-Used_Mortgage_Balance)-Formula_Now) -> Choose your rate change to see this | D30: € | E30: ƒx =Repayment_Now+PMT(New_Rate/12,Used_Years_Left*12,-Used_Mortgage_Balance)-Formula_Now
B31: Change over a year | C31: =IF(Need_1<>"",Need_1,Monthly_Change*12) -> Choose your rate change to see this | D31: € | E31: ƒx =Monthly_Change*12
B32: Repayment now by formula | C32: =IF(Need_3<>"",Need_3,PMT(Used_Current_Rate/12,Used_Years_Left*12,-Used_Mortgage_Balance)) -> Choose your mortgage balance to see this | D32: € | E32: ƒx =PMT(Used_Current_Rate/12,Used_Years_Left*12,-Used_Mortgage_Balance)
B33: New rate (never below 0%) | C33: =IF(Need_4<>"",Need_4,MAX(0,Used_Current_Rate+Rate_Change)) -> Choose your rate change to see this | D33: % | E33: ƒx =MAX(0,Used_Current_Rate+Rate_Change)
B35: HOW IT WORKS
B36: • Repayment = PMT(rate ÷ 12, years left × 12, −balance) at the current and the new rate.
B37: • The change is the difference between the two; a stated repayment moves by the same amount.
B38: Edge rules and validation:
B39: • The new rate is floored at 0% (Irish mortgages have not had negative rates).
B40: • At 0% interest Excel's PMT/NPER/FV give amount ÷ months, so no special case is needed in Excel; in code use payment = amount / months.
B42: ADD TO MY PLAN (what this calculator sends to the plan)
B43: Goal | C43: ="No goal" -> No goal | E43: ƒx ="No goal"
B45: CHOICES STILL NEEDED (helper rows: blank = all inputs a result needs are filled)
B46: Needs: rate change, Used_Actual_Repayment, Used_Current_Rate, Used_Mortgage_Balance, Used_Years_Left | C46: =IF(Rate_Change="","Choose your rate change to see this",IF(NOT(ISNUMBER(Used_Mortgage_Balance)),IF(Used_Mortgage_Balance="",IF(Mortgage_Balance="","Choose your mortgage balance to see this",""),Used_Mortgage_Balance),IF(NOT(ISNUMBER(Used_Years_Left)),IF(Used_Years_Left="",IF(Years_Left="","Choose your years left to see this",""),Used_Years_Left),IF(NOT(ISNUMBER(Used_Actual_Repayment)),IF(Used_Actual_Repayment="","Choose your actual monthly repayment to see this",Used_Actual_Repayment),IF(NOT(ISNUMBER(Used_Current_Rate)),IF(Used_Current_Rate="",IF(Current_Rate="","Choose your mortgage rate to see this",""),Used_Current_Rate),""))))) -> Choose your rate change to see this
B47: Needs: Used_Actual_Repayment, Used_Current_Rate, Used_Mortgage_Balance, Used_Years_Left | C47: =IF(NOT(ISNUMBER(Used_Mortgage_Balance)),IF(Used_Mortgage_Balance="",IF(Mortgage_Balance="","Choose your mortgage balance to see this",""),Used_Mortgage_Balance),IF(NOT(ISNUMBER(Used_Years_Left)),IF(Used_Years_Left="",IF(Years_Left="","Choose your years left to see this",""),Used_Years_Left),IF(NOT(ISNUMBER(Used_Actual_Repayment)),IF(Used_Actual_Repayment="","Choose your actual monthly repayment to see this",Used_Actual_Repayment),IF(NOT(ISNUMBER(Used_Current_Rate)),IF(Used_Current_Rate="",IF(Current_Rate="","Choose your mortgage rate to see this",""),Used_Current_Rate),"")))) -> Choose your mortgage balance to see this
...

Sheet C06 Term comparison
B1: C06 · Mortgage term comparison | E1: Category: Home & Mortgage · prototype id: term
B2: Question it answers: Shorter or longer term: what is the trade-off? | E2: =IF(Fill_Example="Yes","Example values are ON (README): grey Example only figures fill blank inputs.","Blank template: fill the yellow inputs (or switch on example values on the README).") -> Blank template: fill the yellow inputs (or switch on example values on the README).
B3: Compares two mortgage terms: the monthly repayment and the total interest of each.
B5: FROM YOUR STATEMENT (filled automatically by the document reader)
B6: Document: Mortgage statement (annual statement of account) or offer letter. Blank = no statement uploaded, or the figure is not on it. Grey-blue cells are filled by the reader (you can type here to test).
B7: Outstanding balance | D7: € | E7: Allowed: €0 to €10,000,000 | G7: Reader field: see note
B8: Interest rate | D8: % | E8: Allowed: 0% to 15% | G8: Reader field: see note
B9: Term remaining | D9: years | E9: Allowed: 0 to 40 | G9: Reader field: see note
B10: Statement date | D10: date | E10: Allowed: a date (dd/mm/yyyy) | G10: Reader field: see note
B12: OR TYPE IT YOURSELF | C12: Your figure | D12: Unit | E12: Allowed | F12: Example only (grey; used only when "Fill example values" is Yes)
B13: Mortgage amount | D13: € | E13: Type 3 · your figure · Your own figure. In the app it is pre-filled from Your finances / statement: balance. Allowed: €50,000 to €10,000,000 · steps of €1,000 | F13: 300000 | G13: =IF(ISBLANK(C13),IF(Fill_Example="Yes",F13,""),C13)
B14: Interest rate | D14: % | E14: ="Type 2 · your figure · Your own rate (your statement shows it; typing it is fine, no upload needed). "&IF(ISNUMBER(Suggest_Mortgage_Rate),"Suggested: "&TEXT(Suggest_Mortgage_Rate,"0.00%")&" · "&Suggest_Mortgage_Rate_Label&". ","No suggestion. ")&"Enter your own figure."&" In the app it is pre-filled from Your finances / statement: rate. Enter your own figure. Allowed: 1% to 8% · steps of 0.05%" -> Type 2 · your figure · Your own rate (your statement shows it; typing it is fine, no upload needed). Suggested: 3.48% · Central Bank of Ireland: average rate on new mortgages, Jul 2026. Enter your own figure. In the app it is pre-filled from Your finances / statement: rate. Enter your own figure. Allowed: 1% to 8% · steps of 0.05% | F14: =IF(ISNUMBER(Suggest_Mortgage_Rate),Suggest_Mortgage_Rate,"") -> 0.0348 | G14: =IF(ISBLANK(C14),IF(Fill_Example="Yes",F14,""),C14)
B15: Term A | D15: years | E15: Type 3 · your figure · Your own figure. In the app it is pre-filled from Years left (25 if not given). Allowed: 5 to 35 · steps of 1 | F15: 25 | G15: =IF(AND(ISNUMBER(C15),N(C15)<5),"",IF(ISBLANK(C15),IF(Fill_Example="Yes",F15,""),C15))
B16: Term B | D16: years | E16: Type 3 · your figure · Your own figure. Allowed: 5 to 35 · steps of 1 | F16: 35 | G16: =IF(AND(ISNUMBER(C16),N(C16)<5),"",IF(ISBLANK(C16),IF(Fill_Example="Yes",F16,""),C16))
B18: FIGURE USED (statement figure if present, else your figure)
B19: Mortgage amount | C19: =IF(ISBLANK(Stmt_Balance),Loan_Amount,Stmt_Balance) | D19: =IF(ISBLANK(Stmt_Balance),"Your figure","From your statement") -> Your figure | E19: ƒx =IF(ISBLANK(Stmt_Balance),Loan_Amount,Stmt_Balance)
B20: Interest rate | C20: =IF(ISBLANK(Stmt_Rate),Interest_Rate,Stmt_Rate) | D20: =IF(ISBLANK(Stmt_Rate),"Your figure","From your statement") -> Your figure | E20: ƒx =IF(ISBLANK(Stmt_Rate),Interest_Rate,Stmt_Rate)
B21: Term A | C21: =IF(ISBLANK(Stmt_Term),Term_A,Stmt_Term) | D21: =IF(ISBLANK(Stmt_Term),"Your figure","From your statement") -> Your figure | E21: ƒx =IF(ISBLANK(Stmt_Term),Term_A,Stmt_Term)
B22: Statement date check | C22: =IF(ISBLANK(Stmt_Statement_Date),"",IF(TODAY()-Stmt_Statement_Date>Statement_Max_Age_Days,"Needs a look: statement is more than 12 months old","Up to date")) | E22: ƒx =IF(ISBLANK(Stmt_Statement_Date),"",IF(TODAY()-Stmt_Statement_Date>Statement_Max_Age_Days,"Needs a look: statement is more than 12 months old","Up to date"))
B24: RESULTS | C24: Result | D24: Shown as | E24: Formula
B25: Interest difference | C25: =IF(Need_1<>"",Need_1,ABS(Interest_B-Interest_A)) -> Choose your term B to see this | D25: =IF(Need_1<>"",Need_1,IF(Used_Term_A=Term_B,"Both terms are the same.","The "&MIN(Used_Term_A,Term_B)&"-year term costs more each month but less interest overall.")) -> Choose your term B to see this | E25: ƒx =ABS(Interest_B-Interest_A)
B26: Term A: monthly repayment | C26: =IF(Need_2<>"",Need_2,PMT(Used_Interest_Rate/12,Used_Term_A*12,-Used_Loan_Amount)) -> Choose your mortgage amount to see this | D26: € | E26: ƒx =PMT(Used_Interest_Rate/12,Used_Term_A*12,-Used_Loan_Amount)
B27: Term B: monthly repayment | C27: =IF(Need_3<>"",Need_3,PMT(Used_Interest_Rate/12,Term_B*12,-Used_Loan_Amount)) -> Choose your term B to see this | D27: € | E27: ƒx =PMT(Used_Interest_Rate/12,Term_B*12,-Used_Loan_Amount)
B28: Term A: total interest | C28: =IF(Need_2<>"",Need_2,Monthly_A*Used_Term_A*12-Used_Loan_Amount) -> Choose your mortgage amount to see this | D28: € | E28: ƒx =Monthly_A*Used_Term_A*12-Used_Loan_Amount
B29: Term B: total interest | C29: =IF(Need_3<>"",Need_3,Monthly_B*Term_B*12-Used_Loan_Amount) -> Choose your term B to see this | D29: € | E29: ƒx =Monthly_B*Term_B*12-Used_Loan_Amount
B31: HOW IT WORKS
B32: • Monthly = PMT(rate ÷ 12, term × 12, −amount) for each term.
B33: • Total interest = monthly × months − amount.
B34: Edge rules and validation:
B35: • Equal terms show "Both terms are the same."
B36: • At 0% interest Excel's PMT/NPER/FV give amount ÷ months, so no special case is needed in Excel; in code use payment = amount / months.
B38: ADD TO MY PLAN (what this calculator sends to the plan)
B39: Goal | C39: ="No goal" -> No goal | E39: ƒx ="No goal"
B41: CHOICES STILL NEEDED (helper rows: blank = all inputs a result needs are filled)
B42: Needs: term B, Used_Interest_Rate, Used_Loan_Amount, Used_Term_A | C42: =IF(Term_B="","Choose your term B to see this",IF(NOT(ISNUMBER(Used_Loan_Amount)),IF(Used_Loan_Amount="",IF(Loan_Amount="","Choose your mortgage amount to see this",""),Used_Loan_Amount),IF(NOT(ISNUMBER(Used_Term_A)),IF(Used_Term_A="",IF(Term_A="","Choose your term A to see this",""),Used_Term_A),IF(NOT(ISNUMBER(Used_Interest_Rate)),IF(Used_Interest_Rate="",IF(Interest_Rate="","Choose your mortgage rate to see this",""),Used_Interest_Rate),"")))) -> Choose your term B to see this
