Workbook

Sheet README
A1: LifeGoals calculators: engineering workbook
A2: Version | B2: Version 1.0 · 1 Oct 2026
A3: Source file | B3: LifeGoals-Customer-Journey-Prototype.html (the CALCS array and its helpers fvL, fvA, pmt, payoff, lasts, pensionAt, todayM, inflation via S.infl, the "Adjust for inflation" switch and the Central Bank borrowing rules).
A4: Purpose | B4: An exact, cell-by-cell replica of every calculator in the prototype so the tool engineer can build them in the real system. Each calculator sheet reproduces the prototype's run(v) function step by step, with the same rounding, loop caps and edge rules. Every test case on the "Test cases" sheet was computed by running the prototype's own code in a headless browser and matched by this workbook (see calculator-verification-report.md).
A5: Numbering | B5: C01 to C28, in the exact order of the CALCS array in the prototype. The same numbers are used in the UI/UX designer's Word spec. Sheet tab = C-number + short name.
A6: How to read a calculator sheet | B6: 1. INPUTS: the sliders, with unit, default, min, max (slider), max if typed (euro fields accept up to 10× the slider top), step and where the prototype pre-fills the value from. 2. WHAT-IF INPUTS: the "What if…" card, where the tool has one. 3. CONTEXT INPUTS: other state the function reads (a stated repayment, a pension statement, the "Adjust for inflation" switch). 4. CALCULATION: every intermediate step as its own labelled row, with the JS it mirrors. 5. OUTPUTS: exactly the figures the prototype shows; "Value" is the full-precision number, "As shown in the prototype" is the text the customer sees (same rounding and wording rules), blank when the prototype does not show it. 6. Helper tables (to the right, from column K): one row per month or year for every loop in the JS, to the same cap.
A7: Colour legend | B7: Blue text = input you can change · Yellow fill = key assumption · Black text = formula · Green text = link to another sheet (the Assumptions sheet) · Green fill = output.
A8: Percentages | B8: Stored as fractions (4% = 0.04). The prototype holds most rates as whole percentages (4) and divides by 100; the results are the same.
A9: Inflation | B9: The client's own choice (Assumptions!C6 and C7). Default here: chosen, 2% (long-term standard). 3.5% is Ireland today (CSO, May 2026). With C6 = 0 the workbook behaves like the prototype before the client picks a rate (nominal figures, flat withdrawals).
A10: Growth set | B10: Standard (default) or Cautious, on Assumptions!C8. Only the pay-rise rate is used inside a calculator (C12); the other rates only pre-fill inputs.
A11: Rounding | B11: Money is shown to whole euros as the prototype does (eur(): round the absolute value, then a "−€" sign for negatives). Cells keep full precision. Month counts use yrs(): "N yr(s) M mo", or "M months" under a year.
A12: Functions used | B12: Excel 2007-compatible only: IF, AND, MAX, MIN, ABS, INT, MOD, ROUND, POWER, SQRT, SUM, INDEX, MATCH, FIXED. No XLOOKUP, FILTER, SEQUENCE, LET or LAMBDA. PMT/FV/NPER are not used: the annuity is written out so it matches the JS at 0% too, and loops are explicit tables (no closed-form NPER).
A13: Out of scope | B13: The main plan cashflow and goal-funding engine (project()) is not in this workbook; it is documented separately.
... A15: Sheets | B15: README · Index · Assumptions · C01 Borrowing · C02 Mortgage repayment · C03 Deposit · C04 Mortgage overpayment · C05 Interest rate impact · C06 Term comparison · C07 Rent vs buy · C08 Goal planner · C09 Compound growth · C10 Lump sum growth · C11 Emergency fund · C12 Retirement projection · C13 Contribution impact · C14 AVC impact · C15 Will my money last · C16 Drawdown scenarios · C17 Inflation adjusted return · C18 Regular investing · C19 Fees impact · C20 Risk and return · C21 Life cover · C22 Income protection gap · C23 Mortgage protection · C24 Net worth · C25 Monthly surplus · C26 Budget 50 30 20 · C27 Debt repayment · C28 Loan repayment · Test cases
A17: Legend samples
A18: Input
A19: Key assumption
A20: Formula
A21: Cross-sheet link

Sheet Index
A1: C-number | B1: Sheet | C1: Category | D1: Calculator | E1: Question shown | F1: Inputs (incl. what-if and context) | G1: Outputs
A2: C01 | B2: =HYPERLINK("#'C01 Borrowing'!A1","C01 Borrowing") -> C01 Borrowing | C2: Home & Mortgage | D2: How much could I borrow? | E2: What home price could be within reach? | F2: Your gross income; Partner income; Deposit saved; First-time buyer (1 = yes, 0 = no); Interest rate; Term; [what-if] Save extra towards deposit | G2: Homes up to about; Income multiple used (in the sentence); Limit that sets the amount (in the sentence); Borrowing by income (lti×); Borrowing by deposit (90% LTV); Your deposit; Monthly repayment (illustrative); "Add to my plan" goal amount (Buy a home); "Add to my plan" goal years
A3: C02 | B3: =HYPERLINK("#'C02 Mortgage repayment'!A1","C02 Mortgage repayment") -> C02 Mortgage repayment | C3: Home & Mortgage | D3: Monthly mortgage repayment | E3: What would my monthly repayment be? | F3: Mortgage amount; Interest rate; Term; [what-if] If rates changed by; [context] Stated monthly mortgage repayment (0 = none); [context] Customer has not moved loan, rate or term in this tool (1 = yes) | G3: Headline: monthly repayment (what-if repayment when dr ≠ 0); What-if: change vs now (in the sentence); Formula repayment (when the stated figure differs by ≥ €5); Repayment now; Change over a year; Mortgage free in (months); Total interest; Total repaid; "Add to my plan" goal amount; "Add to my plan" goal years
A4: C03 | B4: =HYPERLINK("#'C03 Deposit'!A1","C03 Deposit") -> C03 Deposit | C4: Home & Mortgage | D4: Deposit calculator | E4: How long until I have my deposit? | F4: Home price; Deposit needed; Saved so far; Monthly saving; [what-if] Save extra each month | G4: Time to your deposit (months); You need (sentence); Saving a month (sentence); Deposit needed; Still to save; "Add to my plan" goal amount (Home deposit); "Add to my plan" goal years
A5: C04 | B5: =HYPERLINK("#'C04 Mortgage overpayment'!A1","C04 Mortgage overpayment") -> C04 Mortgage overpayment | C5: Home & Mortgage | D5: Mortgage overpayment | E5: What if I paid a little extra each month? | F5: Mortgage balance; Interest rate; Years left; Extra each month; [context] Stated monthly mortgage repayment (0 = none); [context] Customer has not moved balance, rate or years in this tool (1 = yes) | G5: Mortgage free sooner by (months); Extra a month (sentence); On top of (repayment now, sentence); Mortgage free now in (months); With the extra (months); Interest saved; "Add to my plan" goal amount (Mortgage free); "Add to my plan" goal years
A6: C05 | B6: =HYPERLINK("#'C05 Interest rate impact'!A1","C05 Interest rate impact") -> C05 Interest rate impact | C6: Home & Mortgage | D6: Interest-rate impact | E6: What if my mortgage rate changed? | F6: Mortgage balance; Current rate; Years left; Rate change; [context] Stated monthly mortgage repayment (0 = none); [context] Customer has not moved balance, rate or years in this tool (1 = yes) | G6: Monthly change; New rate (sentence); Now; After change; Change over a year
A7: C06 | B7: =HYPERLINK("#'C06 Term comparison'!A1","C06 Term comparison") -> C06 Term comparison | C7: Home & Mortgage | D7: Mortgage term comparison | E7: Shorter or longer term: what is the trade-off? | F7: Mortgage amount; Interest rate; Term A; Term B | G7: Interest difference; Shorter term named in the sentence (years); Term A monthly; Term B monthly; Term A total interest; Term B total interest
A8: C07 | B8: =HYPERLINK("#'C07 Rent vs buy'!A1","C07 Rent vs buy") -> C07 Rent vs buy | C8: Home & Mortgage | D8: Rent vs buy | E8: How do renting and buying compare over time? | F8: Monthly rent; Home price; Deposit; Mortgage rate; Years; House price growth | G8: Home equity after the years; Rent paid; Interest + upkeep (buying); Home value; "Add to my plan" goal amount (Buy a home); "Add to my plan" goal years
A9: C08 | B9: =HYPERLINK("#'C08 Goal planner'!A1","C08 Goal planner") -> C08 Goal planner | C9: Savings & Goals | D9: Goal planner | E9: How much a month to reach my goal? | F9: Goal amount (today's prices); Years until the goal; Already saved; Growth / interest | G9: Monthly amount (illustrative); Goal in today's prices; Will cost about (in y yrs); Will cost about (sentence); Already saved; Inflation rate quoted (sentence); "Add to my plan" goal amount (My goal); "Add to my plan" goal years
A10: C09 | B10: =HYPERLINK("#'C09 Compound growth'!A1","C09 Compound growth") -> C09 Compound growth | C10: Savings & Goals | D10: Compound growth | E10: What could regular saving grow into? | F10: Starting amount; Monthly addition; Growth rate; Years | G10: Could grow to; Paid in; Illustrative growth; Worth in today's money (prices rising [inflation] a year); Worth about … in today's money (sentence); "Add to my plan" goal amount (Build wealth); "Add to my plan" goal years
A11: C10 | B11: =HYPERLINK("#'C10 Lump sum growth'!A1","C10 Lump sum growth") -> C10 Lump sum growth | C11: Investments | D11: Lump-sum growth | E11: What could a one-off amount become? | F11: Amount; Growth rate; Years; Yearly fees; [context] "Adjust for inflation" switch (1 = on) | G11: Headline figure; Real return a year (sentence); Growth after fees quoted (sentence); Cost of waiting (sentence); If you start today; If you start in 5 years; Worth in today's money (prices rising [inflation] a year); Fees cost; "Add to my plan" goal amount (Build wealth); "Add to my plan" goal years
A12: C11 | B12: =HYPERLINK("#'C11 Emergency fund'!A1","C11 Emergency fund") -> C11 Emergency fund | C12: Savings & Goals | D12: Emergency fund | E12: How strong is my financial cushion? | F12: Essential monthly spending; Months you want covered; Easy-access savings | G12: You currently have (months); Your target is (sentence); You are … away (sentence); Target cushion; Still to build; "Add to my plan" goal amount (Emergency fund); "Add to my plan" goal years
A13: C12 | B13: =HYPERLINK("#'C12 Retirement projection'!A1","C12 Retirement projection") -> C12 Retirement projection | C13: Pensions & Retirement | D13: Retirement projection | E13: Could your current path fund the retirement you want? | F13: Your age; Target retirement age; Pension value today; Monthly contributions; Desired yearly income; Other yearly income (e.g. State Pension); Growth after charges; [what-if] Retire later by; [what-if] Save more each month; [what-if] Spend less in retirement (per year); [context] Pension statement projection available (1 = yes); [context] Statement's projected fund; [context] Statement's retirement age; [context] Customer has not moved pot, contributions, growth or age in this tool (1 = yes) | G13: Projected fund; Illustrative gap of (sentence); Pay rise quoted (sentence); Illustrative target (25 × the income you need); Illustrative gap; Retiring at; Worth in today's money (prices rising [inflation] a year); Your statement projects (age nra); On our assumptions (age ra); "Add to my plan" goal amount (Comfortable retirement); "Add to my plan" goal years
A14: C13 | B14: =HYPERLINK("#'C13 Contribution impact'!A1","C13 Contribution impact") -> C13 Contribution impact | C14: Pensions & Retirement | D14: Contribution impact | E14: What difference would a small increase make? | F14: Salary; Increase contributions by; Years to retirement; Growth assumption; Your tax rate | G14: Could add to your pension; Extra per month; Cost after tax relief; Worth in today's money (prices rising [inflation] a year); "Add to my plan" goal amount (Boost my pension); "Add to my plan" goal years
A15: C14 | B15: =HYPERLINK("#'C14 AVC impact'!A1","C14 AVC impact") -> C14 AVC impact | C15: Pensions & Retirement | D15: AVC impact | E15: What could extra voluntary contributions add? | F15: AVC per month; Years to retirement; Growth assumption; Your tax rate | G15: Could add; Each AVC could cost about (sentence); Paid in; Net cost to you; Worth in today's money (prices rising [inflation] a year); "Add to my plan" goal amount (Boost my pension); "Add to my plan" goal years
A16: C15 | B16: =HYPERLINK("#'C15 Will my money last'!A1","C15 Will my money last") -> C15 Will my money last | C16: Pensions & Retirement | D16: Will my money last? | E16: How long could my retirement savings last? | F16: Retirement savings; Yearly withdrawal; Growth assumption | G16: Could last about (years); Withdrawing a year (sentence); Withdrawals rise with prices at (sentence); Withdrawal rate
A17: C16 | B17: =HYPERLINK("#'C16 Drawdown scenarios'!A1","C16 Drawdown scenarios") -> C16 Drawdown scenarios | C17: Pensions & Retirement | D17: Retirement drawdown scenarios | E17: How do different growth rates change things? | F17: Retirement savings; Yearly withdrawal | G17: Balanced scenario lasts (years); Cautious (2%); Balanced (4%); Growth (6%); Withdrawals rise with prices at (sentence)
A18: C17 | B18: =HYPERLINK("#'C17 Inflation adjusted return'!A1","C17 Inflation adjusted return") -> C17 Inflation adjusted return | C18: Investments | D18: Inflation-adjusted return | E18: What is my money really worth in future? | F18: Amount; Nominal return; Years | G18: Headline figure; Future value; Real return a year; Value in today's money; Real return (sentence, 1 dp)
A19: C18 | B19: =HYPERLINK("#'C18 Regular investing'!A1","C18 Regular investing") -> C18 Regular investing | C19: Investments | D19: Regular investing | E19: What could investing monthly build? | F19: Monthly amount; Years; Growth assumption; Yearly fees; [context] "Adjust for inflation" switch (1 = on) | G19: Headline figure; Real return a year (sentence); Growth after fees quoted (sentence); Fees quoted (sentence); Fees could cost (sentence); Paid in; Before fees; Fees cost; Worth in today's money (prices rising [inflation] a year); "Add to my plan" goal amount (Build wealth); "Add to my plan" goal years
A20: C19 | B20: =HYPERLINK("#'C19 Fees impact'!A1","C19 Fees impact") -> C19 Fees impact | C20: Investments | D20: Fees impact | E20: How much do fees really cost over time? | F20: Amount invested; Years; Growth before fees; Fee A; Fee B | G20: Difference; Fee difference quoted (sentence); With fee A; With fee B
A21: C20 | B21: =HYPERLINK("#'C20 Risk and return'!A1","C20 Risk and return") -> C20 Risk and return | C21: Investments | D21: Risk & return simulator | E21: What range of outcomes might each style have? | F21: Amount; Years; Style: 1 Cautious · 2 Balanced · 3 Growth | G21: Middle outcome (headline); A difficult year could see a fall of (sentence, %); Weaker outcome; Middle outcome; Stronger outcome
A22: C21 | B22: =HYPERLINK("#'C21 Life cover'!A1","C21 Life cover") -> C21 Life cover | C22: Protection | D22: Life cover estimator | E22: How much cover might my family need? | F22: Your yearly income; Years your family would need support; Mortgage balance; Other debts; Savings & investments; Existing cover (incl. work) | G22: Illustrative cover gap; Income replacement (60%); Debts to clear; Existing cover + savings; "Add to my plan" goal amount (Protect my family); "Add to my plan" goal years
A23: C22 | B23: =HYPERLINK("#'C22 Income protection gap'!A1","C22 Income protection gap") -> C22 Income protection gap | C23: Protection | D23: Income protection gap | E23: How long could I cope if I couldn't work? | F23: Essential monthly spending; Months of sick pay from work; Easy-access savings | G23: You could cope for about (months); Gap a month afterwards (sentence); Sick pay; Savings would cover; "Add to my plan" goal amount (Protect my income); "Add to my plan" goal years
A24: C23 | B24: =HYPERLINK("#'C23 Mortgage protection'!A1","C23 Mortgage protection") -> C23 Mortgage protection | C24: Protection | D24: Mortgage protection | E24: What cover would clear my mortgage? | F24: Mortgage balance; Interest rate; Years left; [context] Stated monthly mortgage repayment (0 = none); [context] Customer has not moved balance, rate or years in this tool (1 = yes) | G24: Cover needed today; Repaying a month (sentence); In 5 years; In 10 years; In 15 years
A25: C24 | B25: =HYPERLINK("#'C24 Net worth'!A1","C24 Net worth") -> C24 Net worth | C25: Everyday Money | D25: Net worth | E25: What am I worth, all in? | F25: Savings; Investments; Pensions; Property value; Mortgage; Other loans | G25: Your net worth; You own; You owe
A26: C25 | B26: =HYPERLINK("#'C25 Monthly surplus'!A1","C25 Monthly surplus") -> C25 Monthly surplus | C26: Everyday Money | D26: Monthly surplus | E26: What is left at the end of the month? | F26: Take-home pay per month; Essentials (rent/mortgage, bills, food); Lifestyle spending; Debt repayments | G26: Monthly surplus; % of take-home free for goals (sentence); Take-home; Going out; "Add to my plan" goal amount (Save my surplus); "Add to my plan" goal years
A27: C26 | B27: =HYPERLINK("#'C26 Budget 50 30 20'!A1","C26 Budget 50 30 20") -> C26 Budget 50 30 20 | C27: Everyday Money | D27: Budget (50/30/20) | E27: A simple way to split your pay | F27: Take-home pay per month | G27: Save each month; Needs (50%); Wants (30%); Savings & debt (20%)
A28: C27 | B28: =HYPERLINK("#'C27 Debt repayment'!A1","C27 Debt repayment") -> C27 Debt repayment | C28: Everyday Money | D28: Debt repayment | E28: How fast can I clear my debt? | F28: Balance; Interest (APR); Monthly payment; [what-if] Pay extra each month | G28: Debt free in (months); You would pay about … in interest (sentence); Total interest; "Add to my plan" goal amount (Debt free); "Add to my plan" goal years
A29: C28 | B29: =HYPERLINK("#'C28 Loan repayment'!A1","C28 Loan repayment") -> C28 Loan repayment | C29: Everyday Money | D29: Loan repayment | E29: What would a loan cost me? | F29: Loan amount; Interest (APR); Years | G29: Monthly repayment; Total interest (sentence); Total repaid

Sheet Assumptions
A1: Assumptions and constants used by the calculators
A2: Every rate, rule and constant a calculator uses sits in its own cell here and is referenced by the calculator sheets (green text there = a link to this sheet). Blue text on yellow = a key assumption you can change. Black = formula.
A4: CLIENT'S CHOICES (change these; every calculator sheet links here)
A5: Key | B5: Assumption | C5: Value | D5: Unit | F5: Source / note
A6: infl_on | B6: Client has chosen an inflation rate (1 = yes, 0 = not chosen yet) | C6: 1 | D6: flag | F6: Prototype state S.infl (null until the client picks). While 0, tools show nominal figures and prompt "Pick an inflation rate"; withdrawals stay flat.
A7: infl | B7: Inflation rate (the client's choice) | C7: 0.02 | D7: % | F7: Client's choice (S.infl): 2% = long-term standard; 3.5% = Ireland today (LifeGoals-Customer-Journey-Prototype.html: INFL_IE, CSO May 2026); or "Other" 0–10%. Default here 2%.
A8: set | B8: Growth assumptions set (Standard or Cautious) | C8: Standard | D8: text | F8: Client's choice (S.assume): Standard (default) or Cautious (the Financial Planner's set). AS_SETS in the prototype.
A10: INFLATION REFERENCE
A11: Key | B11: Assumption | C11: Value | D11: Unit | F11: Source / note
A12: infl_std | B12: Long-term standard inflation (also the internal fallback before the client chooses) | C12: 0.02 | D12: % | F12: INFL_STD = 0.02: planners' long-term standard (2% a year).
A13: infl_ie | B13: Ireland inflation today | C13: 0.035 | D13: % | F13: INFL_IE = 0.035: Ireland today, CSO, May 2026 (INFL_SRC).
A14: infl_eff | B14: Inflation used in calculations (AS.infl) | C14: =IF($C$6=1,$C$7,$C$12) -> 0.02 | D14: % | F14: applyAssume(): AS.infl = S.infl if chosen, else INFL_STD.
A16: GROWTH ASSUMPTIONS BY SET (AS_SETS)
A17: Key | B17: Rate | C17: Standard | D17: Cautious | E17: Active (selected set) | F17: Source / note
A18: wage | B18: Pay rises a year (retirement tool: contributions rise with pay) | C18: 0.025 | D18: 0.03 | E18: =INDEX(C18:D18,MATCH($C$8,$C$17:$D$17,0)) -> 0.025 | F18: LifeGoals-Customer-Journey-Prototype.html: AS_SETS.standard.wage / AS_SETS.cautious.wage
A19: cash | B19: Cash savings growth after tax (plan only; not used by a calculator) | C19: 0.01 | D19: 0.007 | E19: =INDEX(C19:D19,MATCH($C$8,$C$17:$D$17,0)) -> 0.01 | F19: LifeGoals-Customer-Journey-Prototype.html: AS_SETS.standard.cash / AS_SETS.cautious.cash
A20: inv | B20: Investment growth after charges and tax (plan only) | C20: 0.045 | D20: 0.03 | E20: =INDEX(C20:D20,MATCH($C$8,$C$17:$D$17,0)) -> 0.045 | F20: LifeGoals-Customer-Journey-Prototype.html: AS_SETS.standard.inv / AS_SETS.cautious.inv
A21: pen | B21: Pension growth after charges (pre-fills the growth input of retirement, contribution and AVC tools) | C21: 0.045 | D21: 0.04 | E21: =INDEX(C21:D21,MATCH($C$8,$C$17:$D$17,0)) -> 0.045 | F21: LifeGoals-Customer-Journey-Prototype.html: AS_SETS.standard.pen / AS_SETS.cautious.pen
A22: penRet | B22: Pension growth once retired (pre-fills "Will my money last?") | C22: 0.0315 | D22: 0.028 | E22: =INDEX(C22:D22,MATCH($C$8,$C$17:$D$17,0)) -> 0.0315 | F22: LifeGoals-Customer-Journey-Prototype.html: AS_SETS.standard.penRet / AS_SETS.cautious.penRet
A24: CENTRAL BANK OF IRELAND MORTGAGE MEASURES (C01 How much could I borrow?)
A25: Key | B25: Assumption | C25: Value | D25: Unit | F25: Source / note
A26: lti_ftb | B26: Loan-to-income limit, first-time buyers | C26: 4 | D26: n | F26: Central Bank of Ireland mortgage measures (from 1 Jan 2023): 4× gross income for first-time buyers. https://www.centralbank.ie/news/article/central-bank-announces-targeted-changes-to-mortgage-measures-framework
A27: lti_ssb | B27: Loan-to-income limit, second and subsequent buyers | C27: 3.5 | D27: n | F27: Central Bank of Ireland: 3.5× gross income for second and subsequent buyers. https://www.centralbank.ie/news/article/central-bank-announces-targeted-changes-to-mortgage-measures-framework
A28: ltv | B28: Loan-to-value limit (all buyers) | C28: 0.9 | D28: % | F28: Central Bank of Ireland: 90% LTV for first-time and second and subsequent buyers (10% deposit). https://www.centralbank.ie/news/article/central-bank-announces-targeted-changes-to-mortgage-measures-framework
A29: dep_mult | B29: Loan allowed per €1 of deposit at that LTV | C29: =ROUND(C28/(1-C28),10) -> 9 | D29: n | F29: LTV ÷ (1 − LTV) = 9. The prototype hard-codes dep × 9.
A31: FIGURES USED ONLY TO PRE-FILL INPUTS (calcPre; for the engineer's data mapping)
A32: Key | B32: Assumption | C32: Value | D32: Unit | F32: Source / note
A33: pen_typ_chg | B33: Typical pension charges already inside the pension growth rate | C33: 0.01 | D33: % | F33: PEN_TYP_CHG: growth = set rate + 1% − the statement's charges, if a statement gives them.
A34: sp | B34: State Pension a year | C34: 15564 | D34: € | F34: AS.sp: €15,564 a year from age 66. Retirement tool "Other yearly income" = Math.round(State Pension × entitlement factor).
A35: sp_full | B35: State Pension entitlement factor: "Expect full" | C35: 1 | D35: n | F35: finNums().sp
A36: sp_partly | B36: State Pension entitlement factor: "Partly" | C36: 0.6 | D36: n | F36: finNums().sp
A37: sp_notsure | B37: State Pension entitlement factor: "Not sure"/not given | C37: 0.8 | D37: n | F37: finNums().sp
A38: tx_band | B38: Standard-rate income tax band (single) | C38: 44000 | D38: € | F38: TX.band 2026: tax-rate input pre-fills 40% if income > €44,000, else 20%.
A40: CALCULATOR CONSTANTS (hard-coded in the prototype; one cell each)
A41: Key | B41: Assumption | C41: Value | D41: Unit | F41: Source / note
A42: payoff_cap | B42: payoff(): maximum months in the loop | C42: 1200 | D42: n | F42: LifeGoals-Customer-Journey-Prototype.html CALCS: payoff(): while (bal > 0.005 && m < 1200). Used by C02, C04, C27.
A43: payoff_tol | B43: payoff(): balance treated as paid off at or below | C43: 0.005 | D43: € | F43: LifeGoals-Customer-Journey-Prototype.html CALCS: payoff(): ignores a rounding cent so an exact repayment ends on the term.
A44: lasts_cap | B44: lasts(): maximum years in the loop ("60+") | C44: 60 | D44: n | F44: LifeGoals-Customer-Journey-Prototype.html CALCS: lasts(): while (y < 60). Used by C15, C16.
A45: diff_min | B45: Show the formula repayment when the stated one differs by at least | C45: 5 | D45: € | F45: LifeGoals-Customer-Journey-Prototype.html CALCS: repayment: Math.abs(own - calc) >= 5
A46: rb_term | B46: Rent vs buy: mortgage term (years) | C46: 30 | D46: n | F46: LifeGoals-Customer-Journey-Prototype.html CALCS: rentbuy: pmt(loan, v.rate, 30)
...

Sheet C01 Borrowing
A1: C01 · How much could I borrow?
A2: Question shown: "What home price could be within reach?" · Category: Home & Mortgage · Prototype id: borrow
A3: Replicates: CALCS 'borrow' run(v); helper pmt(P, r, y).
A4: Edge rules: Income multiple: 4× for first-time buyers (ftb ≠ 0), 3.5× otherwise. Loan = the lower of income × multiple and deposit × 9 (90% LTV). When the two limits are equal the text says the income limit sets the amount (JS: byDep < byInc). pmt() uses the monthly rate r/12 and, at 0%, P/n.
A5: Legend: blue = input (change these) · black = formula · green = link to the Assumptions sheet · yellow fill = key assumption. Money cells show whole euros but keep full precision, as the prototype does.
A8: INPUTS
A9: Input | B9: Value | C9: Unit | D9: Default | E9: Min | F9: Max (slider) | G9: Max if typed | H9: Step | I9: Pre-filled from (if the prototype pre-fills it)
A10: Your gross income | B10: 60000 | C10: € | D10: 60000 | E10: 15000 | F10: 250000 | G10: 2500000 | H10: 1000 | I10: Your finances: your income (if given)
A11: Partner income | B11: 0 | C11: € | D11: 0 | E11: 0 | F11: 250000 | G11: 2500000 | H11: 1000 | I11: Your finances: partner's income (if given)
A12: Deposit saved | B12: 25000 | C12: € | D12: 25000 | E12: 0 | F12: 200000 | G12: 2000000 | H12: 1000 | I12: Plan: the home goal's amount already saved (if any)
A13: First-time buyer (1 = yes, 0 = no) | B13: 1 | D13: 1 | E13: 0 | F13: 1 | G13: 1 | H13: 1 | I13: Your finances: home status (owns a home → 0, otherwise 1)
A14: Interest rate | B14: 0.04 | C14: % (stored as a fraction) | D14: 0.04 | E14: 0.01 | F14: 0.08 | G14: 0.08 | H14: 0.001
A15: Term | B15: 30 | C15: years | D15: 30 | E15: 10 | F15: 35 | G15: 35 | H15: 1
A17: WHAT-IF INPUTS (the "What if…" card)
A18: Input | B18: Value | C18: Unit | D18: Default | E18: Min | F18: Max (slider) | G18: Max if typed | H18: Step | I18: Pre-filled from (if the prototype pre-fills it)
A19: Save extra towards deposit | B19: 0 | C19: € | D19: 0 | E19: 0 | F19: 50000 | G19: 500000 | H19: 1000
A21: CALCULATION
A22: Calculation step | B22: Value | C22: Unit | D22: JS equivalent (prototype run function)
A23: Income multiple (Central Bank limit) | B23: =IF($B$13<>0,Assumptions!$C$26,Assumptions!$C$27) -> 4 | C23: n | D23: lti = v.ftb ? 4 : 3.5
A24: Deposit incl. what-if extra | B24: =$B$12+$B$19 -> 25000 | C24: € | D24: dep = v.dep + (v.xdep || 0)
A25: Borrowing by income | B25: =($B$10+$B$11)*$B$23 -> 240000 | C25: € | D25: byInc = (v.inc + v.inc2) * lti
A26: Borrowing by deposit (90% LTV) | B26: =$B$24*Assumptions!$C$29 -> 225000 | C26: € | D26: byDep = dep * 9
A27: Loan (lower of the two) | B27: =MIN($B$25,$B$26) -> 225000 | C27: € | D27: loan = Math.min(byInc, byDep)
A28: Home price within reach | B28: =$B$27+$B$24 -> 250000 | C28: € | D28: price = loan + dep
A29: Monthly interest rate | B29: =$B$14/12 -> 0.0033333333 | C29: rate (fraction) | D29: i = r / 100 / 12
A30: Number of monthly payments | B30: =$B$15*12 -> 360 | C30: n | D30: n = y * 12
A31: Monthly repayment (illustrative) | B31: =IF(($B$30)=0,0,IF($B$29<>0,$B$27*$B$29/(1-POWER(1+$B$29,-($B$30))),$B$27/($B$30))) -> 1074.1844 | C31: € | D31: pmt(loan, v.rate, v.term)
A32: Which limit sets the amount | B32: =IF($B$26<$B$25,"deposit","income limit") -> deposit | C32: text | D32: byDep < byInc ? 'deposit' : 'income limit'
A34: OUTPUTS
A35: Output | B35: Value | C35: As shown in the prototype | D35: Shown when / where it appears
A36: Headline label | C36: ="Homes up to about" -> Homes up to about | D36: Always
A37: Homes up to about | B37: =$B$28 -> 250000 | C37: =IF(($B$28)<0,"−€","€")&FIXED(ROUND(ABS($B$28),0),0) -> €250,000 | D37: Headline figure
A38: Income multiple used (in the sentence) | B38: =$B$23 -> 4 | C38: =$B$23&"" -> 4 | D38: Sentence
A39: Limit that sets the amount (in the sentence) | C39: =$B$32 -> deposit | D39: Sentence
A40: Borrowing by income (lti×) | B40: =$B$25 -> 240000 | C40: =IF(($B$25)<0,"−€","€")&FIXED(ROUND(ABS($B$25),0),0) -> €240,000 | D40: Row 1
A41: Borrowing by deposit (90% LTV) | B41: =$B$26 -> 225000 | C41: =IF(($B$26)<0,"−€","€")&FIXED(ROUND(ABS($B$26),0),0) -> €225,000 | D41: Row 2
A42: Your deposit | B42: =$B$24 -> 25000 | C42: =IF(($B$24)<0,"−€","€")&FIXED(ROUND(ABS($B$24),0),0) -> €25,000 | D42: Row 3
A43: Monthly repayment (illustrative) | B43: =$B$31 -> 1074.1844 | C43: =IF(($B$31)<0,"−€","€")&FIXED(ROUND(ABS($B$31),0),0) -> €1,074 | D43: Row 4
A44: "Add to my plan" goal amount (Buy a home) | B44: =INT(($B$28*Assumptions!$C$70)+0.5) -> 25000 | C44: =$B$44&"" -> 25000 | D44: Add to my plan: Math.round(price × 10%)
A45: "Add to my plan" goal years | B45: =Assumptions!$C$71 -> 3 | C45: =$B$45&"" -> 3 | D45: Add to my plan

Sheet C02 Mortgage repayment
A1: C02 · Monthly mortgage repayment
A2: Question shown: "What would my monthly repayment be?" · Category: Home & Mortgage · Prototype id: repayment
A3: Replicates: CALCS 'repayment' run(v); helpers pmt(), payoff(), mine(), statedM().
A4: Edge rules: Uses the customer's stated repayment (statement or typed) instead of the formula while loan, rate and term are untouched. With a what-if rate change (dr ≠ 0) the result is base + pmt(new rate) − pmt(rate) and the payoff rows are hidden. payoff(): month-by-month to 1,200 months; stops when balance ≤ €0.005; returns Infinity ("Not at this repayment") as soon as the payment ≤ that month's interest.
A5: Legend: blue = input (change these) · black = formula · green = link to the Assumptions sheet · yellow fill = key assumption. Money cells show whole euros but keep full precision, as the prototype does. | K5: One row per month, capped at 1,200 months like the JS loop.
K6: Payoff of the mortgage at the current repayment: payoff(v.loan, v.rate, base)
K7: Month | L7: Loop runs this month (bal > 0.005, month ≤ cap, not stopped) | M7: Opening balance | N7: Interest (bal × i) | O7: Closing balance (bal + it − pay) | P7: Payment ≤ interest: never pays off (1) | Q7: Cumulative interest
A8: INPUTS | K8: 1 | L8: =IF(AND(K8<=Assumptions!$C$42,$B$10>Assumptions!$C$43),1,0) -> 1 | M8: =$B$10 -> 300000 | N8: =IF(L8=1,M8*$B$25,0) -> 1000 | O8: =IF(L8=1,M8+N8-$B$29,M8) -> 299567.75 | P8: =IF(L8=1,IF($B$29<=N8,1,0),0) -> 0 | Q8: =N8 -> 1000
A9: Input | B9: Value | C9: Unit | D9: Default | E9: Min | F9: Max (slider) | G9: Max if typed | H9: Step | I9: Pre-filled from (if the prototype pre-fills it) | K9: =K8+1 -> 2 | L9: =IF(AND(K9<=Assumptions!$C$42,L8=1,P8=0,O8>Assumptions!$C$43),1,0) -> 1 | M9: =O8 -> 299567.75 | N9: =IF(L9=1,M9*$B$25,0) -> 998.55918 | O9: =IF(L9=1,M9+N9-$B$29,M9) -> 299134.07 | P9: =IF(L9=1,IF($B$29<=N9,1,0),0) -> 0 | Q9: =Q8+N9 -> 1998.5592
A10: Mortgage amount | B10: 300000 | C10: € | D10: 300000 | E10: 50000 | F10: 1000000 | G10: 10000000 | H10: 1000 | I10: Your finances or mortgage statement: mortgage balance (if you have a mortgage) | K10: =K9+1 -> 3 | L10: =IF(AND(K10<=Assumptions!$C$42,L9=1,P9=0,O9>Assumptions!$C$43),1,0) -> 1 | M10: =O9 -> 299134.07 | N10: =IF(L10=1,M10*$B$25,0) -> 997.11356 | O10: =IF(L10=1,M10+N10-$B$29,M10) -> 298698.94 | P10: =IF(L10=1,IF($B$29<=N10,1,0),0) -> 0 | Q10: =Q9+N10 -> 2995.6727
A11: Interest rate | B11: 0.04 | C11: % (stored as a fraction) | D11: 0.04 | E11: 0.01 | F11: 0.08 | G11: 0.08 | H11: 0.0005 | I11: Your finances or mortgage statement: mortgage rate | K11: =K10+1 -> 4 | L11: =IF(AND(K11<=Assumptions!$C$42,L10=1,P10=0,O10>Assumptions!$C$43),1,0) -> 1 | M11: =O10 -> 298698.94 | N11: =IF(L11=1,M11*$B$25,0) -> 995.66312 | O11: =IF(L11=1,M11+N11-$B$29,M11) -> 298262.35 | P11: =IF(L11=1,IF($B$29<=N11,1,0),0) -> 0 | Q11: =Q10+N11 -> 3991.3359
A12: Term | B12: 30 | C12: years | D12: 30 | E12: 5 | F12: 35 | G12: 35 | H12: 1 | I12: Your finances or mortgage statement: years left (25 if not given) | K12: =K11+1 -> 5 | L12: =IF(AND(K12<=Assumptions!$C$42,L11=1,P11=0,O11>Assumptions!$C$43),1,0) -> 1 | M12: =O11 -> 298262.35 | N12: =IF(L12=1,M12*$B$25,0) -> 994.20784 | O12: =IF(L12=1,M12+N12-$B$29,M12) -> 297824.31 | P12: =IF(L12=1,IF($B$29<=N12,1,0),0) -> 0 | Q12: =Q11+N12 -> 4985.5437
K13: =K12+1 -> 6 | L13: =IF(AND(K13<=Assumptions!$C$42,L12=1,P12=0,O12>Assumptions!$C$43),1,0) -> 1 | M13: =O12 -> 297824.31 | N13: =IF(L13=1,M13*$B$25,0) -> 992.74771 | O13: =IF(L13=1,M13+N13-$B$29,M13) -> 297384.82 | P13: =IF(L13=1,IF($B$29<=N13,1,0),0) -> 0 | Q13: =Q12+N13 -> 5978.2914
A14: WHAT-IF INPUTS (the "What if…" card) | K14: =K13+1 -> 7 | L14: =IF(AND(K14<=Assumptions!$C$42,L13=1,P13=0,O13>Assumptions!$C$43),1,0) -> 1 | M14: =O13 -> 297384.82 | N14: =IF(L14=1,M14*$B$25,0) -> 991.28272 | O14: =IF(L14=1,M14+N14-$B$29,M14) -> 296943.85 | P14: =IF(L14=1,IF($B$29<=N14,1,0),0) -> 0 | Q14: =Q13+N14 -> 6969.5741
A15: Input | B15: Value | C15: Unit | D15: Default | E15: Min | F15: Max (slider) | G15: Max if typed | H15: Step | I15: Pre-filled from (if the prototype pre-fills it) | K15: =K14+1 -> 8 | L15: =IF(AND(K15<=Assumptions!$C$42,L14=1,P14=0,O14>Assumptions!$C$43),1,0) -> 1 | M15: =O14 -> 296943.85 | N15: =IF(L15=1,M15*$B$25,0) -> 989.81284 | O15: =IF(L15=1,M15+N15-$B$29,M15) -> 296501.42 | P15: =IF(L15=1,IF($B$29<=N15,1,0),0) -> 0 | Q15: =Q14+N15 -> 7959.387
A16: If rates changed by | B16: 0 | C16: % (stored as a fraction) | D16: 0 | E16: -0.02 | F16: 0.03 | G16: 0.03 | H16: 0.0025 | K16: =K15+1 -> 9 | L16: =IF(AND(K16<=Assumptions!$C$42,L15=1,P15=0,O15>Assumptions!$C$43),1,0) -> 1 | M16: =O15 -> 296501.42 | N16: =IF(L16=1,M16*$B$25,0) -> 988.33807 | O16: =IF(L16=1,M16+N16-$B$29,M16) -> 296057.51 | P16: =IF(L16=1,IF($B$29<=N16,1,0),0) -> 0 | Q16: =Q15+N16 -> 8947.725
K17: =K16+1 -> 10 | L17: =IF(AND(K17<=Assumptions!$C$42,L16=1,P16=0,O16>Assumptions!$C$43),1,0) -> 1 | M17: =O16 -> 296057.51 | N17: =IF(L17=1,M17*$B$25,0) -> 986.85837 | O17: =IF(L17=1,M17+N17-$B$29,M17) -> 295612.12 | P17: =IF(L17=1,IF($B$29<=N17,1,0),0) -> 0 | Q17: =Q16+N17 -> 9934.5834
A18: CONTEXT INPUTS (state the prototype reads besides the sliders) | K18: =K17+1 -> 11 | L18: =IF(AND(K18<=Assumptions!$C$42,L17=1,P17=0,O17>Assumptions!$C$43),1,0) -> 1 | M18: =O17 -> 295612.12 | N18: =IF(L18=1,M18*$B$25,0) -> 985.37375 | O18: =IF(L18=1,M18+N18-$B$29,M18) -> 295165.25 | P18: =IF(L18=1,IF($B$29<=N18,1,0),0) -> 0 | Q18: =Q17+N18 -> 10919.957
A19: Input | B19: Value | C19: Unit | D19: Default | E19: Min | F19: Max (slider) | G19: Max if typed | H19: Step | I19: Pre-filled from (if the prototype pre-fills it) | K19: =K18+1 -> 12 | L19: =IF(AND(K19<=Assumptions!$C$42,L18=1,P18=0,O18>Assumptions!$C$43),1,0) -> 1 | M19: =O18 -> 295165.25 | N19: =IF(L19=1,M19*$B$25,0) -> 983.88417 | O19: =IF(L19=1,M19+N19-$B$29,M19) -> 294716.89 | P19: =IF(L19=1,IF($B$29<=N19,1,0),0) -> 0 | Q19: =Q18+N19 -> 11903.841
A20: Stated monthly mortgage repayment (0 = none) | B20: 0 | C20: € | D20: 0 | E20: 0 | F20: 100000 | G20: 100000 | I20: Pre-filled from Your finances / mortgage statement: the stated monthly repayment (statement or typed; estimates do not count). 0 = no stated repayment. | K20: =K19+1 -> 13 | L20: =IF(AND(K20<=Assumptions!$C$42,L19=1,P19=0,O19>Assumptions!$C$43),1,0) -> 1 | M20: =O19 -> 294716.89 | N20: =IF(L20=1,M20*$B$25,0) -> 982.38964 | O20: =IF(L20=1,M20+N20-$B$29,M20) -> 294267.03 | P20: =IF(L20=1,IF($B$29<=N20,1,0),0) -> 0 | Q20: =Q19+N20 -> 12886.231
A21: Customer has not moved loan, rate or term in this tool (1 = yes) | B21: 1 | C21: flag | D21: 1 | E21: 0 | F21: 1 | G21: 1 | H21: 1 | I21: mine(): 1 while the customer has not moved any of the listed sliders in this tool; 0 once they have (the stated figure then stops applying). | K21: =K20+1 -> 14 | L21: =IF(AND(K21<=Assumptions!$C$42,L20=1,P20=0,O20>Assumptions!$C$43),1,0) -> 1 | M21: =O20 -> 294267.03 | N21: =IF(L21=1,M21*$B$25,0) -> 980.89011 | O21: =IF(L21=1,M21+N21-$B$29,M21) -> 293815.68 | P21: =IF(L21=1,IF($B$29<=N21,1,0),0) -> 0 | Q21: =Q20+N21 -> 13867.121
K22: =K21+1 -> 15 | L22: =IF(AND(K22<=Assumptions!$C$42,L21=1,P21=0,O21>Assumptions!$C$43),1,0) -> 1 | M22: =O21 -> 293815.68 | N22: =IF(L22=1,M22*$B$25,0) -> 979.3856 | O22: =IF(L22=1,M22+N22-$B$29,M22) -> 293362.82 | P22: =IF(L22=1,IF($B$29<=N22,1,0),0) -> 0 | Q22: =Q21+N22 -> 14846.507
A23: CALCULATION | K23: =K22+1 -> 16 | L23: =IF(AND(K23<=Assumptions!$C$42,L22=1,P22=0,O22>Assumptions!$C$43),1,0) -> 1 | M23: =O22 -> 293362.82 | N23: =IF(L23=1,M23*$B$25,0) -> 977.87606 | O23: =IF(L23=1,M23+N23-$B$29,M23) -> 292908.45 | P23: =IF(L23=1,IF($B$29<=N23,1,0),0) -> 0 | Q23: =Q22+N23 -> 15824.383
A24: Calculation step | B24: Value | C24: Unit | D24: JS equivalent (prototype run function) | K24: =K23+1 -> 17 | L24: =IF(AND(K24<=Assumptions!$C$42,L23=1,P23=0,O23>Assumptions!$C$43),1,0) -> 1 | M24: =O23 -> 292908.45 | N24: =IF(L24=1,M24*$B$25,0) -> 976.3615 | O24: =IF(L24=1,M24+N24-$B$29,M24) -> 292452.56 | P24: =IF(L24=1,IF($B$29<=N24,1,0),0) -> 0 | Q24: =Q23+N24 -> 16800.744
A25: Monthly interest rate | B25: =$B$11/12 -> 0.0033333333 | C25: rate (fraction) | D25: i = r / 100 / 12 | K25: =K24+1 -> 18 | L25: =IF(AND(K25<=Assumptions!$C$42,L24=1,P24=0,O24>Assumptions!$C$43),1,0) -> 1 | M25: =O24 -> 292452.56 | N25: =IF(L25=1,M25*$B$25,0) -> 974.84188 | O25: =IF(L25=1,M25+N25-$B$29,M25) -> 291995.16 | P25: =IF(L25=1,IF($B$29<=N25,1,0),0) -> 0 | Q25: =Q24+N25 -> 17775.586
A26: Number of monthly payments | B26: =$B$12*12 -> 360 | C26: n | D26: n = y * 12 | K26: =K25+1 -> 19 | L26: =IF(AND(K26<=Assumptions!$C$42,L25=1,P25=0,O25>Assumptions!$C$43),1,0) -> 1 | M26: =O25 -> 291995.16 | N26: =IF(L26=1,M26*$B$25,0) -> 973.3172 | O26: =IF(L26=1,M26+N26-$B$29,M26) -> 291536.23 | P26: =IF(L26=1,IF($B$29<=N26,1,0),0) -> 0 | Q26: =Q25+N26 -> 18748.903
A27: Formula repayment | B27: =IF(($B$26)=0,0,IF($B$25<>0,$B$10*$B$25/(1-POWER(1+$B$25,-($B$26))),$B$10/($B$26))) -> 1432.2459 | C27: € | D27: calc = pmt(v.loan, v.rate, v.term) | K27: =K26+1 -> 20 | L27: =IF(AND(K27<=Assumptions!$C$42,L26=1,P26=0,O26>Assumptions!$C$43),1,0) -> 1 | M27: =O26 -> 291536.23 | N27: =IF(L27=1,M27*$B$25,0) -> 971.78744 | O27: =IF(L27=1,M27+N27-$B$29,M27) -> 291075.77 | P27: =IF(L27=1,IF($B$29<=N27,1,0),0) -> 0 | Q27: =Q26+N27 -> 19720.691
A28: Stated repayment in use (0 = none) | B28: =IF(AND($B$21=1,$B$20>0),$B$20,0) -> 0 | C28: € | D28: own = mine(...) ? statedM('mortPayM') : null | K28: =K27+1 -> 21 | L28: =IF(AND(K28<=Assumptions!$C$42,L27=1,P27=0,O27>Assumptions!$C$43),1,0) -> 1 | M28: =O27 -> 291075.77 | N28: =IF(L28=1,M28*$B$25,0) -> 970.25258 | O28: =IF(L28=1,M28+N28-$B$29,M28) -> 290613.78 | P28: =IF(L28=1,IF($B$29<=N28,1,0),0) -> 0 | Q28: =Q27+N28 -> 20690.943
A29: Repayment now | B29: =IF($B$28>0,$B$28,$B$27) -> 1432.2459 | C29: € | D29: base = own || calc | K29: =K28+1 -> 22 | L29: =IF(AND(K29<=Assumptions!$C$42,L28=1,P28=0,O28>Assumptions!$C$43),1,0) -> 1 | M29: =O28 -> 290613.78 | N29: =IF(L29=1,M29*$B$25,0) -> 968.7126 | O29: =IF(L29=1,M29+N29-$B$29,M29) -> 290150.25 | P29: =IF(L29=1,IF($B$29<=N29,1,0),0) -> 0 | Q29: =Q28+N29 -> 21659.656
A30: What-if rate | B30: =$B$11+$B$16 -> 0.04 | C30: % (fraction) | D30: r = v.rate + (v.dr || 0) | K30: =K29+1 -> 23 | L30: =IF(AND(K30<=Assumptions!$C$42,L29=1,P29=0,O29>Assumptions!$C$43),1,0) -> 1 | M30: =O29 -> 290150.25 | N30: =IF(L30=1,M30*$B$25,0) -> 967.16749 | O30: =IF(L30=1,M30+N30-$B$29,M30) -> 289685.17 | P30: =IF(L30=1,IF($B$29<=N30,1,0),0) -> 0 | Q30: =Q29+N30 -> 22626.823
A31: What-if monthly rate | B31: =$B$30/12 -> 0.0033333333 | C31: rate (fraction) | K31: =K30+1 -> 24 | L31: =IF(AND(K31<=Assumptions!$C$42,L30=1,P30=0,O30>Assumptions!$C$43),1,0) -> 1 | M31: =O30 -> 289685.17 | N31: =IF(L31=1,M31*$B$25,0) -> 965.61723 | O31: =IF(L31=1,M31+N31-$B$29,M31) -> 289218.54 | P31: =IF(L31=1,IF($B$29<=N31,1,0),0) -> 0 | Q31: =Q30+N31 -> 23592.441
A32: Formula repayment at the what-if rate | B32: =IF(($B$26)=0,0,IF($B$31<>0,$B$10*$B$31/(1-POWER(1+$B$31,-($B$26))),$B$10/($B$26))) -> 1432.2459 | C32: € | D32: pmt(v.loan, r, v.term) | K32: =K31+1 -> 25 | L32: =IF(AND(K32<=Assumptions!$C$42,L31=1,P31=0,O31>Assumptions!$C$43),1,0) -> 1 | M32: =O31 -> 289218.54 | N32: =IF(L32=1,M32*$B$25,0) -> 964.0618 | O32: =IF(L32=1,M32+N32-$B$29,M32) -> 288750.36 | P32: =IF(L32=1,IF($B$29<=N32,1,0),0) -> 0 | Q32: =Q31+N32 -> 24556.502
A33: What-if repayment | B33: =IF($B$16<>0,$B$29+$B$32-$B$27,$B$29) -> 1432.2459 | C33: € | D33: m = v.dr ? base + pmt(v.loan, r, v.term) - calc : base | K33: =K32+1 -> 26 | L33: =IF(AND(K33<=Assumptions!$C$42,L32=1,P32=0,O32>Assumptions!$C$43),1,0) -> 1 | M33: =O32 -> 288750.36 | N33: =IF(L33=1,M33*$B$25,0) -> 962.50118 | O33: =IF(L33=1,M33+N33-$B$29,M33) -> 288280.61 | P33: =IF(L33=1,IF($B$29<=N33,1,0),0) -> 0 | Q33: =Q32+N33 -> 25519.004
A34: Payoff never ends (1 = payment ≤ interest) | B34: =MAX($P$8:$P$1207) -> 0 | C34: flag | D34: po.m === Infinity | K34: =K33+1 -> 27 | L34: =IF(AND(K34<=Assumptions!$C$42,L33=1,P33=0,O33>Assumptions!$C$43),1,0) -> 1 | M34: =O33 -> 288280.61 | N34: =IF(L34=1,M34*$B$25,0) -> 960.93537 | O34: =IF(L34=1,M34+N34-$B$29,M34) -> 287809.3 | P34: =IF(L34=1,IF($B$29<=N34,1,0),0) -> 0 | Q34: =Q33+N34 -> 26479.939
A35: Months to mortgage free | B35: =SUM($L$8:$L$1207) -> 360 | C35: n | D35: po.m (payoff months) | K35: =K34+1 -> 28 | L35: =IF(AND(K35<=Assumptions!$C$42,L34=1,P34=0,O34>Assumptions!$C$43),1,0) -> 1 | M35: =O34 -> 287809.3 | N35: =IF(L35=1,M35*$B$25,0) -> 959.36433 | O35: =IF(L35=1,M35+N35-$B$29,M35) -> 287336.42 | P35: =IF(L35=1,IF($B$29<=N35,1,0),0) -> 0 | Q35: =Q34+N35 -> 27439.303
A36: Total interest | B36: =$Q$1207 -> 215608.52 | C36: € | D36: po.int | K36: =K35+1 -> 29 | L36: =IF(AND(K36<=Assumptions!$C$42,L35=1,P35=0,O35>Assumptions!$C$43),1,0) -> 1 | M36: =O35 -> 287336.42 | N36: =IF(L36=1,M36*$B$25,0) -> 957.78806 | O36: =IF(L36=1,M36+N36-$B$29,M36) -> 286861.96 | P36: =IF(L36=1,IF($B$29<=N36,1,0),0) -> 0 | Q36: =Q35+N36 -> 28397.091
A37: Stated figure differs from formula by ≥ €5 (1 = yes) | B37: =IF(AND($B$28>0,ABS($B$28-$B$27)>=Assumptions!$C$45),1,0) -> 0 | C37: flag | D37: own && Math.abs(own - calc) >= 5 | K37: =K36+1 -> 30 | L37: =IF(AND(K37<=Assumptions!$C$42,L36=1,P36=0,O36>Assumptions!$C$43),1,0) -> 1 | M37: =O36 -> 286861.96 | N37: =IF(L37=1,M37*$B$25,0) -> 956.20654 | O37: =IF(L37=1,M37+N37-$B$29,M37) -> 286385.92 | P37: =IF(L37=1,IF($B$29<=N37,1,0),0) -> 0 | Q37: =Q36+N37 -> 29353.298
K38: =K37+1 -> 31 | L38: =IF(AND(K38<=Assumptions!$C$42,L37=1,P37=0,O37>Assumptions!$C$43),1,0) -> 1 | M38: =O37 -> 286385.92 | N38: =IF(L38=1,M38*$B$25,0) -> 954.61974 | O38: =IF(L38=1,M38+N38-$B$29,M38) -> 285908.3 | P38: =IF(L38=1,IF($B$29<=N38,1,0),0) -> 0 | Q38: =Q37+N38 -> 30307.918
A39: OUTPUTS | K39: =K38+1 -> 32 | L39: =IF(AND(K39<=Assumptions!$C$42,L38=1,P38=0,O38>Assumptions!$C$43),1,0) -> 1 | M39: =O38 -> 285908.3 | N39: =IF(L39=1,M39*$B$25,0) -> 953.02765 | O39: =IF(L39=1,M39+N39-$B$29,M39) -> 285429.08 | P39: =IF(L39=1,IF($B$29<=N39,1,0),0) -> 0 | Q39: =Q38+N39 -> 31260.945
A40: Output | B40: Value | C40: As shown in the prototype | D40: Shown when / where it appears | K40: =K39+1 -> 33 | L40: =IF(AND(K40<=Assumptions!$C$42,L39=1,P39=0,O39>Assumptions!$C$43),1,0) -> 1 | M40: =O39 -> 285429.08 | N40: =IF(L40=1,M40*$B$25,0) -> 951.43026 | O40: =IF(L40=1,M40+N40-$B$29,M40) -> 284948.26 | P40: =IF(L40=1,IF($B$29<=N40,1,0),0) -> 0 | Q40: =Q39+N40 -> 32212.376
...

Sheet C03 Deposit
A1: C03 · Deposit calculator
A2: Question shown: "How long until I have my deposit?" · Category: Home & Mortgage · Prototype id: deposit
A3: Replicates: CALCS 'deposit' run(v); helper yrs(m).
A4: Edge rules: Closed form in the JS (no loop): months = ceil(still to save ÷ monthly saving incl. what-if extra). "You have it" when nothing is left to save. Goal years = max(1, ceil(unrounded months ÷ 12)). yrs() shows "N months" below a year (also "1 months", "0 months").
A5: Legend: blue = input (change these) · black = formula · green = link to the Assumptions sheet · yellow fill = key assumption. Money cells show whole euros but keep full precision, as the prototype does.
A8: INPUTS
A9: Input | B9: Value | C9: Unit | D9: Default | E9: Min | F9: Max (slider) | G9: Max if typed | H9: Step | I9: Pre-filled from (if the prototype pre-fills it)
A10: Home price | B10: 350000 | C10: € | D10: 350000 | E10: 100000 | F10: 1000000 | G10: 10000000 | H10: 5000
A11: Deposit needed | B11: 0.1 | C11: % (stored as a fraction) | D11: 0.1 | E11: 0.05 | F11: 0.3 | G11: 0.3 | H11: 0.01
A12: Saved so far | B12: 12000 | C12: € | D12: 12000 | E12: 0 | F12: 200000 | G12: 2000000 | H12: 500 | I12: Plan: the home goal's amount already saved (if any)
A13: Monthly saving | B13: 800 | C13: € | D13: 800 | E13: 50 | F13: 5000 | G13: 50000 | H13: 50
A15: WHAT-IF INPUTS (the "What if…" card)
A16: Input | B16: Value | C16: Unit | D16: Default | E16: Min | F16: Max (slider) | G16: Max if typed | H16: Step | I16: Pre-filled from (if the prototype pre-fills it)
A17: Save extra each month | B17: 0 | C17: € | D17: 0 | E17: 0 | F17: 1500 | G17: 15000 | H17: 50
A19: CALCULATION
A20: Calculation step | B20: Value | C20: Unit | D20: JS equivalent (prototype run function)
A21: Deposit needed | B21: =$B$10*$B$11 -> 35000 | C21: € | D21: need = v.price * v.pc / 100
A22: Still to save | B22: =MAX(0,$B$21-$B$12) -> 23000 | C22: € | D22: left = Math.max(0, need - v.saved)
A23: Monthly saving incl. what-if extra | B23: =$B$13+$B$17 -> 800 | C23: € | D23: v.mo + (v.xmo || 0)
A24: Months (unrounded) | B24: =IF($B$23=0,0,$B$22/$B$23) -> 28.75 | C24: num | D24: m = left / (v.mo + (v.xmo || 0)) [0 saving is outside the input range]
A25: Months (rounded up) | B25: =(-INT(-($B$24))) -> 29 | C25: n | D25: Math.ceil(m)
A27: OUTPUTS
A28: Output | B28: Value | C28: As shown in the prototype | D28: Shown when / where it appears
A29: Headline label | C29: ="Time to your deposit" -> Time to your deposit | D29: Always
A30: Time to your deposit (months) | B30: =IF($B$22<>0,$B$25,0) -> 29 | C30: =IF($B$22<>0,IF(INT($B$25/12)>0,INT($B$25/12)&" yr"&IF(INT($B$25/12)>1,"s","")&IF(ROUND(MOD($B$25,12),0)<>0," "&ROUND(MOD($B$25,12),0)&" mo",""),ROUND(MOD($B$25,12),0)&" months"),"You have it") -> 2 yrs 5 mo | D30: Headline
A31: You need (sentence) | B31: =$B$21 -> 35000 | C31: =IF(($B$21)<0,"−€","€")&FIXED(ROUND(ABS($B$21),0),0) -> €35,000 | D31: Sentence
A32: Saving a month (sentence) | B32: =$B$23 -> 800 | C32: =IF(($B$23)<0,"−€","€")&FIXED(ROUND(ABS($B$23),0),0) -> €800 | D32: Sentence
A33: Deposit needed | B33: =$B$21 -> 35000 | C33: =IF(($B$21)<0,"−€","€")&FIXED(ROUND(ABS($B$21),0),0) -> €35,000 | D33: Row 1
A34: Still to save | B34: =$B$22 -> 23000 | C34: =IF(($B$22)<0,"−€","€")&FIXED(ROUND(ABS($B$22),0),0) -> €23,000 | D34: Row 2
A35: "Add to my plan" goal amount (Home deposit) | B35: =INT(($B$21)+0.5) -> 35000 | C35: =$B$35&"" -> 35000 | D35: Add to my plan
A36: "Add to my plan" goal years | B36: =MAX(1,(-INT(-($B$24/12)))) -> 3 | C36: =$B$36&"" -> 3 | D36: Add to my plan

Sheet C04 Mortgage overpayment
A1: C04 · Mortgage overpayment
A2: Question shown: "What if I paid a little extra each month?" · Category: Home & Mortgage · Prototype id: overpay
A3: Replicates: CALCS 'overpay' run(v); helpers pmt(), payoff() ×2, mine(), statedM(), yrs().
A4: Edge rules: Repayment = stated repayment while balance, rate and years are untouched, else pmt(). Two payoffs: at the repayment (A) and at repayment + extra (B). Headline "—" if A never pays off. If B never pays off either, the row shows "Infinity yrs" and the goal years Infinity (JS behaviour, replicated). Both payoffs stop at 1,200 months.
A5: Legend: blue = input (change these) · black = formula · green = link to the Assumptions sheet · yellow fill = key assumption. Money cells show whole euros but keep full precision, as the prototype does. | K5: One row per month, capped at 1,200 months like the JS loop. | S5: One row per month, capped at 1,200 months like the JS loop.
K6: A: payoff(v.bal, v.rate, p) | S6: B: payoff(v.bal, v.rate, p + v.x)
K7: Month | L7: Loop runs this month (bal > 0.005, month ≤ cap, not stopped) | M7: Opening balance | N7: Interest (bal × i) | O7: Closing balance (bal + it − pay) | P7: Payment ≤ interest: never pays off (1) | Q7: Cumulative interest | S7: Month | T7: Loop runs this month (bal > 0.005, month ≤ cap, not stopped) | U7: Opening balance | V7: Interest (bal × i) | W7: Closing balance (bal + it − pay) | X7: Payment ≤ interest: never pays off (1) | Y7: Cumulative interest
A8: INPUTS | K8: 1 | L8: =IF(AND(K8<=Assumptions!$C$42,$B$10>Assumptions!$C$43),1,0) -> 1 | M8: =$B$10 -> 250000 | N8: =IF(L8=1,M8*$B$22,0) -> 833.33333 | O8: =IF(L8=1,M8+N8-$B$26,M8) -> 249513.74 | P8: =IF(L8=1,IF($B$26<=N8,1,0),0) -> 0 | Q8: =N8 -> 833.33333 | S8: 1 | T8: =IF(AND(S8<=Assumptions!$C$42,$B$10>Assumptions!$C$43),1,0) -> 1 | U8: =$B$10 -> 250000 | V8: =IF(T8=1,U8*$B$22,0) -> 833.33333 | W8: =IF(T8=1,U8+V8-$B$27,U8) -> 249313.74 | X8: =IF(T8=1,IF($B$27<=V8,1,0),0) -> 0 | Y8: =V8 -> 833.33333
A9: Input | B9: Value | C9: Unit | D9: Default | E9: Min | F9: Max (slider) | G9: Max if typed | H9: Step | I9: Pre-filled from (if the prototype pre-fills it) | K9: =K8+1 -> 2 | L9: =IF(AND(K9<=Assumptions!$C$42,L8=1,P8=0,O8>Assumptions!$C$43),1,0) -> 1 | M9: =O8 -> 249513.74 | N9: =IF(L9=1,M9*$B$22,0) -> 831.71247 | O9: =IF(L9=1,M9+N9-$B$26,M9) -> 249025.86 | P9: =IF(L9=1,IF($B$26<=N9,1,0),0) -> 0 | Q9: =Q8+N9 -> 1665.0458 | S9: =S8+1 -> 2 | T9: =IF(AND(S9<=Assumptions!$C$42,T8=1,X8=0,W8>Assumptions!$C$43),1,0) -> 1 | U9: =W8 -> 249313.74 | V9: =IF(T9=1,U9*$B$22,0) -> 831.0458 | W9: =IF(T9=1,U9+V9-$B$27,U9) -> 248625.19 | X9: =IF(T9=1,IF($B$27<=V9,1,0),0) -> 0 | Y9: =Y8+V9 -> 1664.3791
A10: Mortgage balance | B10: 250000 | C10: € | D10: 250000 | E10: 20000 | F10: 1000000 | G10: 10000000 | H10: 1000 | I10: Your finances or mortgage statement: mortgage balance | K10: =K9+1 -> 3 | L10: =IF(AND(K10<=Assumptions!$C$42,L9=1,P9=0,O9>Assumptions!$C$43),1,0) -> 1 | M10: =O9 -> 249025.86 | N10: =IF(L10=1,M10*$B$22,0) -> 830.08621 | O10: =IF(L10=1,M10+N10-$B$26,M10) -> 248536.36 | P10: =IF(L10=1,IF($B$26<=N10,1,0),0) -> 0 | Q10: =Q9+N10 -> 2495.132 | S10: =S9+1 -> 3 | T10: =IF(AND(S10<=Assumptions!$C$42,T9=1,X9=0,W9>Assumptions!$C$43),1,0) -> 1 | U10: =W9 -> 248625.19 | V10: =IF(T10=1,U10*$B$22,0) -> 828.75065 | W10: =IF(T10=1,U10+V10-$B$27,U10) -> 247934.35 | X10: =IF(T10=1,IF($B$27<=V10,1,0),0) -> 0 | Y10: =Y9+V10 -> 2493.1298
A11: Interest rate | B11: 0.04 | C11: % (stored as a fraction) | D11: 0.04 | E11: 0.01 | F11: 0.08 | G11: 0.08 | H11: 0.0005 | I11: Your finances or mortgage statement: mortgage rate | K11: =K10+1 -> 4 | L11: =IF(AND(K11<=Assumptions!$C$42,L10=1,P10=0,O10>Assumptions!$C$43),1,0) -> 1 | M11: =O10 -> 248536.36 | N11: =IF(L11=1,M11*$B$22,0) -> 828.45452 | O11: =IF(L11=1,M11+N11-$B$26,M11) -> 248045.22 | P11: =IF(L11=1,IF($B$26<=N11,1,0),0) -> 0 | Q11: =Q10+N11 -> 3323.5865 | S11: =S10+1 -> 4 | T11: =IF(AND(S11<=Assumptions!$C$42,T10=1,X10=0,W10>Assumptions!$C$43),1,0) -> 1 | U11: =W10 -> 247934.35 | V11: =IF(T11=1,U11*$B$22,0) -> 826.44784 | W11: =IF(T11=1,U11+V11-$B$27,U11) -> 247241.21 | X11: =IF(T11=1,IF($B$27<=V11,1,0),0) -> 0 | Y11: =Y10+V11 -> 3319.5776
A12: Years left | B12: 25 | C12: years | D12: 25 | E12: 3 | F12: 35 | G12: 35 | H12: 1 | I12: Your finances or mortgage statement: years left (25 if not given) | K12: =K11+1 -> 5 | L12: =IF(AND(K12<=Assumptions!$C$42,L11=1,P11=0,O11>Assumptions!$C$43),1,0) -> 1 | M12: =O11 -> 248045.22 | N12: =IF(L12=1,M12*$B$22,0) -> 826.81739 | O12: =IF(L12=1,M12+N12-$B$26,M12) -> 247552.44 | P12: =IF(L12=1,IF($B$26<=N12,1,0),0) -> 0 | Q12: =Q11+N12 -> 4150.4039 | S12: =S11+1 -> 5 | T12: =IF(AND(S12<=Assumptions!$C$42,T11=1,X11=0,W11>Assumptions!$C$43),1,0) -> 1 | U12: =W11 -> 247241.21 | V12: =IF(T12=1,U12*$B$22,0) -> 824.13736 | W12: =IF(T12=1,U12+V12-$B$27,U12) -> 246545.75 | X12: =IF(T12=1,IF($B$27<=V12,1,0),0) -> 0 | Y12: =Y11+V12 -> 4143.715
A13: Extra each month | B13: 200 | C13: € | D13: 200 | E13: 0 | F13: 2000 | G13: 20000 | H13: 25 | K13: =K12+1 -> 6 | L13: =IF(AND(K13<=Assumptions!$C$42,L12=1,P12=0,O12>Assumptions!$C$43),1,0) -> 1 | M13: =O12 -> 247552.44 | N13: =IF(L13=1,M13*$B$22,0) -> 825.17481 | O13: =IF(L13=1,M13+N13-$B$26,M13) -> 247058.03 | P13: =IF(L13=1,IF($B$26<=N13,1,0),0) -> 0 | Q13: =Q12+N13 -> 4975.5787 | S13: =S12+1 -> 6 | T13: =IF(AND(S13<=Assumptions!$C$42,T12=1,X12=0,W12>Assumptions!$C$43),1,0) -> 1 | U13: =W12 -> 246545.75 | V13: =IF(T13=1,U13*$B$22,0) -> 821.81918 | W13: =IF(T13=1,U13+V13-$B$27,U13) -> 245847.98 | X13: =IF(T13=1,IF($B$27<=V13,1,0),0) -> 0 | Y13: =Y12+V13 -> 4965.5342
K14: =K13+1 -> 7 | L14: =IF(AND(K14<=Assumptions!$C$42,L13=1,P13=0,O13>Assumptions!$C$43),1,0) -> 1 | M14: =O13 -> 247058.03 | N14: =IF(L14=1,M14*$B$22,0) -> 823.52675 | O14: =IF(L14=1,M14+N14-$B$26,M14) -> 246561.96 | P14: =IF(L14=1,IF($B$26<=N14,1,0),0) -> 0 | Q14: =Q13+N14 -> 5799.1055 | S14: =S13+1 -> 7 | T14: =IF(AND(S14<=Assumptions!$C$42,T13=1,X13=0,W13>Assumptions!$C$43),1,0) -> 1 | U14: =W13 -> 245847.98 | V14: =IF(T14=1,U14*$B$22,0) -> 819.49327 | W14: =IF(T14=1,U14+V14-$B$27,U14) -> 245147.88 | X14: =IF(T14=1,IF($B$27<=V14,1,0),0) -> 0 | Y14: =Y13+V14 -> 5785.0274
A15: CONTEXT INPUTS (state the prototype reads besides the sliders) | K15: =K14+1 -> 8 | L15: =IF(AND(K15<=Assumptions!$C$42,L14=1,P14=0,O14>Assumptions!$C$43),1,0) -> 1 | M15: =O14 -> 246561.96 | N15: =IF(L15=1,M15*$B$22,0) -> 821.8732 | O15: =IF(L15=1,M15+N15-$B$26,M15) -> 246064.24 | P15: =IF(L15=1,IF($B$26<=N15,1,0),0) -> 0 | Q15: =Q14+N15 -> 6620.9787 | S15: =S14+1 -> 8 | T15: =IF(AND(S15<=Assumptions!$C$42,T14=1,X14=0,W14>Assumptions!$C$43),1,0) -> 1 | U15: =W14 -> 245147.88 | V15: =IF(T15=1,U15*$B$22,0) -> 817.15961 | W15: =IF(T15=1,U15+V15-$B$27,U15) -> 244445.45 | X15: =IF(T15=1,IF($B$27<=V15,1,0),0) -> 0 | Y15: =Y14+V15 -> 6602.1871
A16: Input | B16: Value | C16: Unit | D16: Default | E16: Min | F16: Max (slider) | G16: Max if typed | H16: Step | I16: Pre-filled from (if the prototype pre-fills it) | K16: =K15+1 -> 9 | L16: =IF(AND(K16<=Assumptions!$C$42,L15=1,P15=0,O15>Assumptions!$C$43),1,0) -> 1 | M16: =O15 -> 246064.24 | N16: =IF(L16=1,M16*$B$22,0) -> 820.21414 | O16: =IF(L16=1,M16+N16-$B$26,M16) -> 245564.86 | P16: =IF(L16=1,IF($B$26<=N16,1,0),0) -> 0 | Q16: =Q15+N16 -> 7441.1928 | S16: =S15+1 -> 9 | T16: =IF(AND(S16<=Assumptions!$C$42,T15=1,X15=0,W15>Assumptions!$C$43),1,0) -> 1 | U16: =W15 -> 244445.45 | V16: =IF(T16=1,U16*$B$22,0) -> 814.81817 | W16: =IF(T16=1,U16+V16-$B$27,U16) -> 243740.68 | X16: =IF(T16=1,IF($B$27<=V16,1,0),0) -> 0 | Y16: =Y15+V16 -> 7417.0052
A17: Stated monthly mortgage repayment (0 = none) | B17: 0 | C17: € | D17: 0 | E17: 0 | F17: 100000 | G17: 100000 | I17: Pre-filled from Your finances / mortgage statement: the stated monthly repayment (statement or typed; estimates do not count). 0 = no stated repayment. | K17: =K16+1 -> 10 | L17: =IF(AND(K17<=Assumptions!$C$42,L16=1,P16=0,O16>Assumptions!$C$43),1,0) -> 1 | M17: =O16 -> 245564.86 | N17: =IF(L17=1,M17*$B$22,0) -> 818.54955 | O17: =IF(L17=1,M17+N17-$B$26,M17) -> 245063.82 | P17: =IF(L17=1,IF($B$26<=N17,1,0),0) -> 0 | Q17: =Q16+N17 -> 8259.7424 | S17: =S16+1 -> 10 | T17: =IF(AND(S17<=Assumptions!$C$42,T16=1,X16=0,W16>Assumptions!$C$43),1,0) -> 1 | U17: =W16 -> 243740.68 | V17: =IF(T17=1,U17*$B$22,0) -> 812.46892 | W17: =IF(T17=1,U17+V17-$B$27,U17) -> 243033.55 | X17: =IF(T17=1,IF($B$27<=V17,1,0),0) -> 0 | Y17: =Y16+V17 -> 8229.4741
A18: Customer has not moved balance, rate or years in this tool (1 = yes) | B18: 1 | C18: flag | D18: 1 | E18: 0 | F18: 1 | G18: 1 | H18: 1 | I18: mine(): 1 while the customer has not moved any of the listed sliders in this tool; 0 once they have (the stated figure then stops applying). | K18: =K17+1 -> 11 | L18: =IF(AND(K18<=Assumptions!$C$42,L17=1,P17=0,O17>Assumptions!$C$43),1,0) -> 1 | M18: =O17 -> 245063.82 | N18: =IF(L18=1,M18*$B$22,0) -> 816.8794 | O18: =IF(L18=1,M18+N18-$B$26,M18) -> 244561.11 | P18: =IF(L18=1,IF($B$26<=N18,1,0),0) -> 0 | Q18: =Q17+N18 -> 9076.6218 | S18: =S17+1 -> 11 | T18: =IF(AND(S18<=Assumptions!$C$42,T17=1,X17=0,W17>Assumptions!$C$43),1,0) -> 1 | U18: =W17 -> 243033.55 | V18: =IF(T18=1,U18*$B$22,0) -> 810.11184 | W18: =IF(T18=1,U18+V18-$B$27,U18) -> 242324.07 | X18: =IF(T18=1,IF($B$27<=V18,1,0),0) -> 0 | Y18: =Y17+V18 -> 9039.586
K19: =K18+1 -> 12 | L19: =IF(AND(K19<=Assumptions!$C$42,L18=1,P18=0,O18>Assumptions!$C$43),1,0) -> 1 | M19: =O18 -> 244561.11 | N19: =IF(L19=1,M19*$B$22,0) -> 815.2037 | O19: =IF(L19=1,M19+N19-$B$26,M19) -> 244056.72 | P19: =IF(L19=1,IF($B$26<=N19,1,0),0) -> 0 | Q19: =Q18+N19 -> 9891.8255 | S19: =S18+1 -> 12 | T19: =IF(AND(S19<=Assumptions!$C$42,T18=1,X18=0,W18>Assumptions!$C$43),1,0) -> 1 | U19: =W18 -> 242324.07 | V19: =IF(T19=1,U19*$B$22,0) -> 807.74691 | W19: =IF(T19=1,U19+V19-$B$27,U19) -> 241612.23 | X19: =IF(T19=1,IF($B$27<=V19,1,0),0) -> 0 | Y19: =Y18+V19 -> 9847.3329
A20: CALCULATION | K20: =K19+1 -> 13 | L20: =IF(AND(K20<=Assumptions!$C$42,L19=1,P19=0,O19>Assumptions!$C$43),1,0) -> 1 | M20: =O19 -> 244056.72 | N20: =IF(L20=1,M20*$B$22,0) -> 813.5224 | O20: =IF(L20=1,M20+N20-$B$26,M20) -> 243550.65 | P20: =IF(L20=1,IF($B$26<=N20,1,0),0) -> 0 | Q20: =Q19+N20 -> 10705.348 | S20: =S19+1 -> 13 | T20: =IF(AND(S20<=Assumptions!$C$42,T19=1,X19=0,W19>Assumptions!$C$43),1,0) -> 1 | U20: =W19 -> 241612.23 | V20: =IF(T20=1,U20*$B$22,0) -> 805.37409 | W20: =IF(T20=1,U20+V20-$B$27,U20) -> 240898.01 | X20: =IF(T20=1,IF($B$27<=V20,1,0),0) -> 0 | Y20: =Y19+V20 -> 10652.707
A21: Calculation step | B21: Value | C21: Unit | D21: JS equivalent (prototype run function) | K21: =K20+1 -> 14 | L21: =IF(AND(K21<=Assumptions!$C$42,L20=1,P20=0,O20>Assumptions!$C$43),1,0) -> 1 | M21: =O20 -> 243550.65 | N21: =IF(L21=1,M21*$B$22,0) -> 811.8355 | O21: =IF(L21=1,M21+N21-$B$26,M21) -> 243042.89 | P21: =IF(L21=1,IF($B$26<=N21,1,0),0) -> 0 | Q21: =Q20+N21 -> 11517.183 | S21: =S20+1 -> 14 | T21: =IF(AND(S21<=Assumptions!$C$42,T20=1,X20=0,W20>Assumptions!$C$43),1,0) -> 1 | U21: =W20 -> 240898.01 | V21: =IF(T21=1,U21*$B$22,0) -> 802.99337 | W21: =IF(T21=1,U21+V21-$B$27,U21) -> 240181.41 | X21: =IF(T21=1,IF($B$27<=V21,1,0),0) -> 0 | Y21: =Y20+V21 -> 11455.7
A22: Monthly interest rate | B22: =$B$11/12 -> 0.0033333333 | C22: rate (fraction) | D22: i = r / 100 / 12 | K22: =K21+1 -> 15 | L22: =IF(AND(K22<=Assumptions!$C$42,L21=1,P21=0,O21>Assumptions!$C$43),1,0) -> 1 | M22: =O21 -> 243042.89 | N22: =IF(L22=1,M22*$B$22,0) -> 810.14298 | O22: =IF(L22=1,M22+N22-$B$26,M22) -> 242533.44 | P22: =IF(L22=1,IF($B$26<=N22,1,0),0) -> 0 | Q22: =Q21+N22 -> 12327.326 | S22: =S21+1 -> 15 | T22: =IF(AND(S22<=Assumptions!$C$42,T21=1,X21=0,W21>Assumptions!$C$43),1,0) -> 1 | U22: =W21 -> 240181.41 | V22: =IF(T22=1,U22*$B$22,0) -> 800.6047 | W22: =IF(T22=1,U22+V22-$B$27,U22) -> 239462.42 | X22: =IF(T22=1,IF($B$27<=V22,1,0),0) -> 0 | Y22: =Y21+V22 -> 12256.305
A23: Number of monthly payments | B23: =$B$12*12 -> 300 | C23: n | D23: n = y * 12 | K23: =K22+1 -> 16 | L23: =IF(AND(K23<=Assumptions!$C$42,L22=1,P22=0,O22>Assumptions!$C$43),1,0) -> 1 | M23: =O22 -> 242533.44 | N23: =IF(L23=1,M23*$B$22,0) -> 808.44482 | O23: =IF(L23=1,M23+N23-$B$26,M23) -> 242022.3 | P23: =IF(L23=1,IF($B$26<=N23,1,0),0) -> 0 | Q23: =Q22+N23 -> 13135.771 | S23: =S22+1 -> 16 | T23: =IF(AND(S23<=Assumptions!$C$42,T22=1,X22=0,W22>Assumptions!$C$43),1,0) -> 1 | U23: =W22 -> 239462.42 | V23: =IF(T23=1,U23*$B$22,0) -> 798.20808 | W23: =IF(T23=1,U23+V23-$B$27,U23) -> 238741.04 | X23: =IF(T23=1,IF($B$27<=V23,1,0),0) -> 0 | Y23: =Y22+V23 -> 13054.513
